Workbook

Sheet stok-gudang
A1: nama barang | B1: segel | C1: sellin | D1: total stok
A3: SP ZERO | B3: =index!B4 -> 100 | C3: =index!C4 -> 0 | D3: =B3+C3 -> 100
A4: SP 3GB injek | B4: =index!B5 -> 4413 | C4: =index!C5 -> 15 | D4: =B4+C4 -> 4428
A5: SP 3GB ori | B5: =index!B6 -> 70 | C5: =index!C6 -> 8 | D5: =B5+C5 -> 78
A6: SP 9GB | B6: =index!B7 -> 0 | C6: =index!C7 -> 0 | D6: =B6+C6 -> 0
A7: SP 10GB | B7: =index!B8 -> 746 | C7: =index!C8 -> 0 | D7: =B7+C7 -> 746
B8: =index!B9 -> 0 | C8: =index!C9 -> 0 | D8: =B8+C8 -> 0
A9: VDK | B9: =index!B10 -> 7649 | C9: =index!C10 -> 0 | D9: =B9+C9 -> 7649
A10: 3GB/14HR | B10: =index!B11 -> 0 | C10: =index!C11 -> 97 | D10: =B10+C10 -> 97
A11: 2,5GB | B11: =index!B12 -> 300 | C11: =index!C12 -> 815 | D11: =B11+C11 -> 1115
A12: FI 3 GB | B12: =index!B13 -> 0 | C12: =index!C13 -> 0 | D12: =B12+C12 -> 0
A13: 3.5GB 5HR | B13: =index!B14 -> 300 | C13: =index!C14 -> 71 | D13: =B13+C13 -> 371
A14: 5GB 5HR | B14: =index!B15 -> 450 | C14: =index!C15 -> 0 | D14: =B14+C14 -> 450
A15: 7GB 7HR | B15: =index!B16 -> 426 | C15: =index!C16 -> 15 | D15: =B15+C15 -> 441
A16: Fi 6GB | B16: =index!B17 -> 0 | C16: =index!C17 -> 0 | D16: =B16+C16 -> 0
A17: Fi 1.5GB/1D | B17: =index!B18 -> 0 | C17: =index!C18 -> 51 | D17: =B17+C17 -> 51
A18: Fi 3GB/1D | B18: =index!B19 -> 0 | C18: =index!C19 -> 0 | D18: =B18+C18 -> 0
A19: Fi 3GB/3D | B19: =index!B20 -> 0 | C19: =index!C20 -> 0 | D19: =B19+C19 -> 0
A20: Fi 5GB/2D | B20: =index!B21 -> 450 | C20: =index!C21 -> 904 | D20: =B20+C20 -> 1354
A21: Fi 5GB/3D | B21: =index!B22 -> 207 | C21: =index!C22 -> 10 | D21: =B21+C21 -> 217

Sheet stok-barang-dse
A1: JENIS BARANG | B1: ANDI | C1: FARHAN | D1: ENDEN | E1: PEBRIAN | F1: SPV | G1: TOTAL
A2: SP ZERO | B2: =index!G5 -> 86 | C2: =index!H5 -> 80 | D2: =index!I5 -> 96 | E2: =index!J5 -> 100 | G2: =SUM(B2:F2) -> 362
A3: SP 3GB INJEK | B3: =index!G6 -> 122 | C3: =index!H6 -> 64 | D3: =index!I6 -> 48 | E3: =index!J6 -> 59 | G3: =SUM(B3:F3) -> 293
A4: SP 3GB ORI | B4: =index!G7 -> 0 | C4: =index!H7 -> 63 | D4: =index!I7 -> 90 | E4: =index!J7 -> 183 | G4: =SUM(B4:F4) -> 336
A5: SP 9GB | B5: =index!G8 -> 0 | C5: =index!H8 -> 0 | D5: =index!I8 -> 0 | E5: =index!J8 -> 5 | G5: =SUM(B5:F5) -> 5
A6: SP 10GB | B6: =index!G9 -> 0 | C6: =index!H9 -> 0 | D6: =index!I9 -> 0 | E6: =index!J9 -> 0 | G6: =SUM(B6:F6) -> 0
B7: =index!G10 -> 0 | C7: =index!H10 -> 0 | D7: =index!I10 -> 0 | E7: =index!J10 -> 0 | G7: =SUM(B7:F7) -> 0
A8: VDK | B8: =index!G11 -> 100 | C8: =index!H11 -> 300 | D8: =index!I11 -> 44 | E8: =index!J11 -> 150 | G8: =SUM(B8:F8) -> 594
A9: Voucher 3GB 14HR | B9: =index!G12 -> 0 | C9: =index!H12 -> 0 | D9: =index!I12 -> 0 | E9: =index!J12 -> 0 | G9: =SUM(B9:F9) -> 0
A10: Voucher 2,5GB | B10: =index!G13 -> 96 | C10: =index!H13 -> 104 | D10: =index!I13 -> 68 | E10: =index!J13 -> 202 | G10: =SUM(B10:F10) -> 470
A11: Freedom Internet 3 GB | B11: =index!G14 -> 0 | C11: =index!H14 -> 0 | D11: =index!I14 -> 0 | E11: =index!J14 -> 0 | G11: =SUM(B11:F11) -> 0
A12: Voucher 3.5GB 5HR | B12: =index!G15 -> 9 | C12: =index!H15 -> 0 | D12: =index!I15 -> 35 | E12: =index!J15 -> 5 | G12: =SUM(B12:F12) -> 49
A13: Voucher 5GB 5HR | B13: =index!G16 -> 32 | C13: =index!H16 -> 50 | D13: =index!I16 -> 23 | E13: =index!J16 -> 16 | G13: =SUM(B13:F13) -> 121
A14: Voucher 7GB 7HR | B14: =index!G17 -> 15 | C14: =index!H17 -> 22 | D14: =index!I17 -> 24 | E14: =index!J17 -> 69 | G14: =SUM(B14:F14) -> 130
A15: Fi 6GB | B15: =index!G18 -> 0 | C15: =index!H18 -> 35 | D15: =index!I18 -> 0 | E15: =index!J18 -> 0 | G15: =SUM(B15:F15) -> 35
A16: Fi 1.5GB/1D | B16: =index!G19 -> 0 | C16: =index!H19 -> 0 | D16: =index!I19 -> 0 | E16: =index!J19 -> 0 | G16: =SUM(B16:F16) -> 0
A17: Fi 3GB/1D | B17: =index!G20 -> 0 | C17: =index!H20 -> 0 | D17: =index!I20 -> 0 | E17: =index!J20 -> 0 | G17: =SUM(B17:F17) -> 0
A18: Fi 3GB/3D | B18: =index!G21 -> 11 | C18: =index!H21 -> 14 | D18: =index!I21 -> 9 | E18: =index!J21 -> 0 | G18: =SUM(B18:F18) -> 34
A19: Fi 5GB/2D | B19: =index!G22 -> 25 | C19: =index!H22 -> 15 | D19: =index!I22 -> 96 | E19: =index!J22 -> 92 | G19: =SUM(B19:F19) -> 228
A20: Fi 5GB/3D | B20: =index!G23 -> 15 | C20: =index!H23 -> 0 | D20: =index!I23 -> 3 | E20: =index!J23 -> 54 | G20: =SUM(B20:F20) -> 72
B21: - | C21: - | D21: - | E21: - | F21: - | G21: =SUM(B21:F21) -> 0
B22: - | C22: - | D22: - | E22: - | F22: - | G22: =SUM(B22:F22) -> 0
A23: TOTAL | B23: =SUM(B2:B22) -> 511 | C23: =SUM(C2:C22) -> 747 | D23: =SUM(D2:D22) -> 536 | E23: =SUM(E2:E22) -> 935 | F23: =SUM(F2:F22) -> 0 | G23: =SUM(G2:G22) -> 2729

Sheet penjualan-salmo
A1: Nama cso | B1: Amount
A2: Muhammad Parhan | B2: =index!O3 -> 32259000
A3: Andi Setiawan | B3: =index!O4 -> 52263000
A4: M. Enden Abdul Latif | B4: =index!O5 -> 43042000
A5: Pebrian Sahri Ramdani | B5: =index!O6 -> 50945000
A6: Grand Total | B6: =SUM(B2:B5) -> 178509000

Sheet penjualan-reguler-new
A1: SP | B1: ="Andi " & TEXT(TODAY()-1, "dd-mmm") -> Andi 12-Aug | C1: Andi | D1: ="Parhan " & TEXT(TODAY()-1, "dd-mmm") -> Parhan 12-Aug | E1: Parhan | F1: ="Enden " & TEXT(TODAY()-1, "dd-mmm") -> Enden 12-Aug | G1: Enden | H1: ="Pebrian " & TEXT(TODAY()-1, "dd-mmm") -> Pebrian 12-Aug | I1: Pebrian | J1: Total Daily | K1: Total PCS | L1: Harga | M1: Total Daily | N1: Total Rp | P1: Nama Barang | Q1: Andi w1 | R1: Andi w2 | S1: Andi w3 | T1: Andi w4 | U1: Total | V1: Parhan w1 | W1: Parhan w2 | X1: Parhan w3 | Y1: Parhan w4 | Z1: Total | AA1: Enden w1 | AB1: Enden w2 | AC1: Enden w3 | AD1: Enden w4 | AE1: Total | AF1: Pebrian w1 | AG1: Pebrian w2 | AH1: Pebrian w3 | AI1: Pebrian w4 | AJ1: Total | AK1: Total Weekly | AL1: Harga | AM1: Amount
A2: SP ZERO | B2: =index!R4 -> 0 | C2: =index!S4 -> 0 | D2: =index!T4 -> 0 | E2: =index!U4 -> 0 | F2: =index!V4 -> 0 | G2: =index!W4 -> 0 | H2: =index!X4 -> 0 | I2: =index!Y4 -> 0 | J2: =B2+D2+F2+H2 -> 0 | K2: =SUM(C2:I2) -> 0 | L2: 11000 | M2: =J2*L2 -> 0 | N2: =K2*L2 -> 0 | P2: SP ZERO | Q2: =index!DG4 -> 0 | R2: =index!DH4 -> 0 | S2: =index!DI4 -> 0 | T2: =index!DJ4 -> 0 | U2: =index!DK4 -> 0 | V2: =index!DL4 -> 0 | W2: =index!DM4 -> 0 | X2: =index!DN4 -> 0 | ... AM2: =index!EC4 -> 539000
A3: SP 3GB INJEK | B3: =index!R5 -> 0 | C3: =index!S5 -> 364 | D3: =index!T5 -> 0 | E3: =index!U5 -> 255 | F3: =index!V5 -> 0 | G3: =index!W5 -> 339 | H3: =index!X5 -> 0 | I3: =index!Y5 -> 303 | J3: =B3+D3+F3+H3 -> 0 | K3: =SUM(C3:I3) -> 1261 | L3: 30000 | M3: =J3*L3 -> 0 | N3: =K3*L3 -> 37830000 | P3: SP 3GB INJEK | Q3: =index!DG5 -> 0 | R3: =index!DH5+index!K37 -> 29 | S3: =index!DI5+index!K42+index!K45 -> 55 | T3: =index!DJ5+index!K49 -> 10 | U3: =index!DK5 -> 4 | V3: =index!DL5 -> 42 | W3: =index!DM5+index!K37 -> 44 | X3: =index!DN5 -> 0 | Y3: =index!DO5 -> 0 | Z3: =index!DP5 -> 61 | AA3: =index!DQ5 -> 80 | AB3: =index!DR5+index!K39 -> 35 | AC3: =index!DS5+index!K43 -> 25 | AD3: =index!DT5+index!K47+index!K50+index!K51 -> 50 | AE3: =index!DU5 -> 90 | AF3: =index!DV5 -> 0 | AG3: =index!DW5+index!K40 -> 25 | AH3: =index!DX5 -> 0 | AI3: =index!DY5+index!K44+index!K48 -> 50 | AJ3: =index!DZ5 -> 0 | AK3: =index!EA5 -> 0 | AL3: =index!EB5 -> 30000 | AM3: =index!EC5 -> 0
A4: SP 3GB ORI | B4: =index!R6 -> 0 | C4: =index!S6 -> 119 | D4: =index!T6 -> 0 | E4: =index!U6 -> 166 | F4: =index!V6 -> 0 | G4: =index!W6 -> 126 | H4: =index!X6 -> 0 | I4: =index!Y6 -> 63 | J4: =B4+D4+F4+H4 -> 0 | K4: =SUM(C4:I4) -> 474 | L4: 25000 | M4: =J4*L4 -> 0 | N4: =K4*L4 -> 11850000 | P4: SP 3GB ORI | Q4: =index!DG6 -> 0 | R4: =index!DH6 -> 5 | S4: =index!DI6 -> 0 | T4: =index!DJ6 -> 0 | U4: =index!DK6 -> 5 | V4: =index!DL6 -> 0 | W4: =index!DM6 -> 4 | X4: =index!DN6 -> 0 | ... AM4: =index!EC6 -> 16800000
A5: SP 9GB | B5: =index!R7 -> 0 | C5: =index!S7 -> 0 | D5: =index!T7 -> 0 | E5: =index!U7 -> 5 | F5: =index!V7 -> 0 | G5: =index!W7 -> 5 | H5: =index!X7 -> 0 | I5: =index!Y7 -> 0 | J5: =B5+D5+F5+H5 -> 0 | K5: =SUM(C5:I5) -> 10 | L5: 40000 | M5: =J5*L5 -> 0 | N5: =K5*L5 -> 400000 | P5: SP 9GB | Q5: =index!DG7 -> 0 | R5: =index!DH7 -> 0 | S5: =index!DI7 -> 0 | T5: =index!DJ7 -> 0 | U5: =index!DK7 -> 0 | V5: =index!DL7 -> 0 | W5: =index!DM7 -> 5 | X5: =index!DN7 -> 0 | ... AM5: =index!EC7 -> 0
A6: SP 10GB | B6: =index!R8 -> 0 | C6: =index!S8 -> 24 | D6: =index!T8 -> 0 | E6: =index!U8 -> 31 | F6: =index!V8 -> 0 | G6: =index!W8 -> 33 | H6: =index!X8 -> 0 | I6: =index!Y8 -> 76 | ... N6: =index!AD8 -> 0 | P6: SP 10GB | Q6: =index!DG9 -> 0 | R6: =index!DH9 -> 0 | S6: =index!DI9 -> 0 | T6: =index!DJ9 -> 0 | U6: =index!DK9 -> 9 | V6: =index!DL9 -> 0 | W6: =index!DM9 -> 0 | X6: =index!DN9 -> 0 | ... AM6: =index!EC9 -> 17339000
A7: TOTAL SP | B7: =SUM(B2:B5) -> 0 | C7: =SUM(C2:C5) -> 483 | D7: =SUM(D2:D5) -> 0 | E7: =SUM(E2:E5) -> 426 | F7: =SUM(F2:F5) -> 0 | G7: =SUM(G2:G5) -> 470 | H7: =SUM(H2:H5) -> 0 | I7: =SUM(I2:I5) -> 366 | ... K7: =SUM(K2:K5) -> 1745 | M7: =SUM(M2:M5) -> 0 | N7: =SUM(N2:N5) -> 50080000 | P7: Total SP | Q7: =index!DG9 -> 0 | R7: =index!DH9 -> 0 | S7: =index!DI9 -> 0 | T7: =index!DJ9 -> 0 | U7: =index!DK9 -> 9 | V7: =index!DL9 -> 0 | W7: =index!DM9 -> 0 | X7: =index!DN9 -> 0 | ... AM7: =index!EC9 -> 17339000
A9: VOUCHER | B9: Daily | C9: Andi | D9: Daily | E9: Parhan | F9: Daily | G9: Enden | H9: Daily | I9: Pebrian | J9: Total Daily | K9: Total PCS | L9: Harga | M9: Total Daily | N9: Total Rp | P9: VOUCHER
A10: VDK | B10: =index!R10 -> 0 | C10: =index!S10 -> 238 | D10: =index!T10 -> 0 | E10: =index!U10 -> 600 | F10: =index!V10 -> 0 | G10: =index!W10 -> 189 | H10: =index!X10 -> 0 | I10: =index!Y10 -> 600 | J10: =B10+D10+F10+H10 -> 0 | K10: =SUM(C10:I10) -> 1627 | L10: 600 | M10: =K10*L10 -> 976200 | N10: =K10*L10 -> 976200 | P10: VDK | Q10: =index!DG12 -> 138 | R10: =index!DH12 -> 100 | S10: =index!DI12 -> 0 | T10: =index!DJ12 -> 0 | U10: =index!DK12 -> 238 | V10: =index!DL12 -> 450 | W10: =index!DM12 -> 150 | X10: =index!DN12 -> 0 | ... AM10: =index!EC12 -> 63000
A11: Voucher 3GB 14HR | B11: =index!R11 -> 0 | C11: =index!S11 -> 0 | D11: =index!T11 -> 0 | E11: =index!U11 -> 27 | F11: =index!V11 -> 0 | G11: =index!W11 -> 25 | H11: =index!X11 -> 0 | I11: =index!Y11 -> 4 | J11: =B11+D11+F11+H11 -> 0 | K11: =SUM(C11:I11) -> 56 | L11: 22500 | M11: =K11*L11 -> 1260000 | N11: =K11*L11 -> 1260000 | P11: Voucher 3GB 14HR | Q11: =index!DG13 -> 0 | R11: =index!DH13 -> 0 | S11: =index!DI13 -> 0 | T11: =index!DJ13 -> 0 | U11: =index!DK13 -> 0 | V11: =index!DL13 -> 0 | W11: =index!DM13 -> 0 | X11: =index!DN13 -> 0 | ... AM11: =index!EC13 -> 0
A12: Voucher 2,5GB | B12: =index!R12 -> 0 | C12: =index!S12 -> 99 | D12: =index!T12 -> 0 | E12: =index!U12 -> 245 | F12: =index!V12 -> 3 | G12: =index!W12 -> 131 | H12: =index!X12 -> 0 | I12: =index!Y12 -> 22 | J12: =B12+D12+F12+H12 -> 3 | K12: =SUM(C12:I12) -> 500 | L12: 13500 | M12: =K12*L12 -> 6750000 | N12: =K12*L12 -> 6750000 | P12: Voucher 2,5GB | Q12: =index!DG14 -> 0 | R12: =index!DH14 -> 12 | S12: =index!DI14 -> 0 | T12: =index!DJ14 -> 0 | U12: =index!DK14 -> 12 | V12: =index!DL14 -> 61 | W12: =index!DM14 -> 55 | X12: =index!DN14 -> 0 | ... AM12: =index!EC14 -> 4266000
A13: Freedom Internet 3 GB | B13: =index!R13 -> 0 | C13: =index!S13 -> 0 | D13: =index!T13 -> 0 | E13: =index!U13 -> 0 | F13: =index!V13 -> 0 | G13: =index!W13 -> 0 | H13: =index!X13 -> 0 | I13: =index!Y13 -> 0 | J13: =B13+D13+F13+H13 -> 0 | K13: =SUM(C13:I13) -> 0 | L13: 20000 | M13: =K13*L13 -> 0 | N13: =K13*L13 -> 0 | P13: Freedom Internet 3 GB | Q13: =index!DG15 -> 0 | R13: =index!DH15 -> 0 | S13: =index!DI15 -> 0 | T13: =index!DJ15 -> 0 | U13: =index!DK15 -> 0 | V13: =index!DL15 -> 0 | W13: =index!DM15 -> 0 | X13: =index!DN15 -> 0 | ... AM13: =index!EC15 -> 0
A14: Voucher 3.5GB 5HR | B14: =index!R14 -> 0 | C14: =index!S14 -> 33 | D14: =index!T14 -> 0 | E14: =index!U14 -> 52 | F14: =index!V14 -> 0 | G14: =index!W14 -> 91 | H14: =index!X14 -> 0 | I14: =index!Y14 -> 107 | J14: =B14+D14+F14+H14 -> 0 | K14: =SUM(C14:I14) -> 283 | L14: 15400 | M14: =K14*L14 -> 4358200 | N14: =K14*L14 -> 4358200 | P14: Voucher 3.5GB 5HR | Q14: =index!DG16 -> 0 | R14: =index!DH16 -> 6 | S14: =index!DI16 -> 0 | T14: =index!DJ16 -> 0 | U14: =index!DK16 -> 6 | V14: =index!DL16 -> 19 | W14: =index!DM16 -> 0 | X14: =index!DN16 -> 0 | ... AM14: =index!EC16 -> 939400
A15: Voucher 5GB 5HR | B15: =index!R15 -> 0 | C15: =index!S15 -> 12 | D15: =index!T15 -> 0 | E15: =index!U15 -> 146 | F15: =index!V15 -> 0 | G15: =index!W15 -> 50 | H15: =index!X15 -> 10 | I15: =index!Y15 -> 60 | J15: =B15+D15+F15+H15 -> 10 | K15: =SUM(C15:I15) -> 278 | L15: 17250 | M15: =K15*L15 -> 4795500 | N15: =K15*L15 -> 4795500 | P15: Voucher 5GB 5HR | Q15: =index!DG17 -> 12 | R15: =index!DH17 -> 0 | S15: =index!DI17 -> 0 | T15: =index!DJ17 -> 0 | U15: =index!DK17 -> 12 | V15: =index!DL17 -> 76 | W15: =index!DM17 -> 70 | X15: =index!DN17 -> 0 | ... AM15: =index!EC17 -> 9780750
A16: Voucher 7GB 7HR | B16: =index!R16 -> 0 | C16: =index!S16 -> 0 | D16: =index!T16 -> 0 | E16: =index!U16 -> 34 | F16: =index!V16 -> 0 | G16: =index!W16 -> 0 | H16: =index!X16 -> 0 | I16: =index!Y16 -> 3 | J16: =B16+D16+F16+H16 -> 0 | K16: =SUM(C16:I16) -> 37 | L16: 23800 | M16: =K16*L16 -> 880600 | N16: =K16*L16 -> 880600 | P16: Voucher 7GB 7HR | Q16: =index!DG18 -> 0 | R16: =index!DH18 -> 0 | S16: =index!DI18 -> 0 | T16: =index!DJ18 -> 0 | U16: =index!DK18 -> 0 | V16: =index!DL18 -> 15 | W16: =index!DM18 -> 19 | X16: =index!DN18 -> 0 | ... AM16: =index!EC18 -> 3332000
A17: Fi 6GB | B17: =index!R17 -> 0 | C17: =index!S17 -> 0 | D17: =index!T17 -> 0 | E17: =index!U17 -> 21 | F17: =index!V17 -> 0 | G17: =index!W17 -> 6 | H17: =index!X17 -> 0 | I17: =index!Y17 -> 0 | J17: =B17+D17+F17+H17 -> 0 | K17: =SUM(C17:I17) -> 27 | L17: 30000 | M17: =K17*L17 -> 810000 | N17: =K17*L17 -> 810000 | P17: Fi 6GB | Q17: =index!DG19 -> 0 | R17: =index!DH19 -> 0 | S17: =index!DI19 -> 0 | T17: =index!DJ19 -> 0 | U17: =index!DK19 -> 0 | V17: =index!DL19 -> 16 | W17: =index!DM19 -> 5 | X17: =index!DN19 -> 0 | ... AM17: =index!EC19 -> 1230000
A18: Fi 1.5GB/1D | B18: =index!R18 -> 0 | C18: =index!S18 -> 114 | D18: =index!T18 -> 0 | E18: =index!U18 -> 135 | F18: =index!V18 -> 0 | G18: =index!W18 -> 105 | H18: =index!X18 -> 0 | I18: =index!Y18 -> 63 | J18: =B18+D18+F18+H18 -> 0 | K18: =SUM(C18:I18) -> 417 | L18: 6900 | M18: =K18*L18 -> 2877300 | N18: =K18*L18 -> 2877300 | P18: Fi 1.5GB/1D | Q18: =index!DG20 -> 0 | R18: =index!DH20 -> 0 | S18: =index!DI20 -> 0 | T18: =index!DJ20 -> 0 | U18: =index!DK20 -> 0 | V18: =index!DL20 -> 0 | W18: =index!DM20 -> 0 | X18: =index!DN20 -> 0 | ... AM18: =index!EC20 -> 0
A19: Fi 3GB/1D | B19: =index!R19 -> 0 | C19: =index!S19 -> 0 | D19: =index!T19 -> 0 | E19: =index!U19 -> 0 | F19: =index!V19 -> 0 | G19: =index!W19 -> 0 | H19: =index!X19 -> 0 | I19: =index!Y19 -> 0 | J19: =B19+D19+F19+H19 -> 0 | K19: =SUM(C19:I19) -> 0 | L19: 7000 | M19: =K19*L19 -> 0 | N19: =K19*L19 -> 0 | P19: Fi 3GB/1D | Q19: =index!DG21 -> 0 | R19: =index!DH21 -> 0 | S19: =index!DI21 -> 0 | T19: =index!DJ21 -> 0 | U19: =index!DK21 -> 0 | V19: =index!DL21 -> 0 | W19: =index!DM21 -> 0 | X19: =index!DN21 -> 0 | ... AM19: =index!EC21 -> 7000
A20: Fi 3GB/3D | B20: =index!R20 -> 0 | C20: =index!S20 -> 0 | D20: =index!T20 -> 0 | E20: =index!U20 -> 31 | F20: =index!V20 -> 0 | G20: =index!W20 -> 6 | H20: =index!X20 -> 0 | I20: =index!Y20 -> 0 | J20: =B20+D20+F20+H20 -> 0 | K20: =SUM(C20:I20) -> 37 | L20: 12000 | M20: =K20*L20 -> 444000 | N20: =K20*L20 -> 444000 | P20: Fi 3GB/3D | Q20: =index!DG22 -> 0 | R20: =index!DH22 -> 0 | S20: =index!DI22 -> 0 | T20: =index!DJ22 -> 0 | U20: =index!DK22 -> 0 | V20: =index!DL22 -> 31 | W20: =index!DM22 -> 0 | X20: =index!DN22 -> 0 | ... AM20: =index!EC22 -> 672000
A21: Fi 5GB/2D | B21: =index!R21 -> 0 | C21: =index!S21 -> 65 | D21: =index!T21 -> 10 | E21: =index!U21 -> 76 | F21: =index!V21 -> 4 | G21: =index!W21 -> 42 | H21: =index!X21 -> 0 | I21: =index!Y21 -> 27 | J21: =B21+D21+F21+H21 -> 14 | K21: =SUM(C21:I21) -> 224 | L21: 9600 | M21: =K21*L21 -> 2150400 | N21: =K21*L21 -> 2150400 | P21: Fi 5GB/2D | Q21: =index!DG23 -> 30 | R21: =index!DH23 -> 35 | S21: =index!DI23 -> 0 | T21: =index!DJ23 -> 0 | U21: =index!DK23 -> 65 | V21: =index!DL23 -> 13 | W21: =index!DM23 -> 63 | X21: =index!DN23 -> 0 | ... AM21: =index!EC23 -> 4070400
A22: Fi 5GB/3D | B22: =index!R22 -> 0 | C22: =index!S22 -> 0 | D22: =index!T22 -> 0 | E22: =index!U22 -> 4 | F22: =index!V22 -> 0 | G22: =index!W22 -> 0 | H22: =index!X22 -> 0 | I22: =index!Y22 -> 1 | J22: =B22+D22+F22+H22 -> 0 | K22: =SUM(C22:I22) -> 5 | L22: 13200 | M22: =K22*L22 -> 66000 | N22: =K22*L22 -> 66000 | P22: Fi 5GB/3D | Q22: =index!DG24 -> 0 | R22: =index!DH24 -> 0 | S22: =index!DI24 -> 0 | T22: =index!DJ24 -> 0 | U22: =index!DK24 -> 0 | V22: =index!DL24 -> 0 | W22: =index!DM24 -> 4 | X22: =index!DN24 -> 0 | ... AM22: =index!EC24 -> 0
A23: TOTAL VOUCHER | B23: =SUM(B10:B22) -> 0 | C23: =SUM(C10:C22) -> 561 | D23: =SUM(D10:D22) -> 10 | E23: =SUM(E10:E22) -> 1371 | F23: =SUM(F10:F22) -> 7 | G23: =SUM(G10:G22) -> 645 | H23: =SUM(H10:H22) -> 10 | I23: =SUM(I10:I22) -> 887 | ... K23: =SUM(K10:K22) -> 3491 | M23: =SUM(M10:M22) -> 25368200 | N23: =SUM(N10:N22) -> 25368200 | P23: TOTAL VOUCHER | Q23: =index!DG25 -> 132 | R23: =index!DH25 -> 162 | S23: =index!DI25 -> 120 | T23: =index!DJ25 -> 0 | U23: =index!DK25 -> 414 | V23: =index!DL25 -> 149 | W23: =index!DM25 -> 191 | X23: =index!DN25 -> 231 | ... AM23: =index!EC25 -> 31311900

Sheet penjualan-paket-jupiter
A1: No. | B1: Tanggal Pengambilan | C1: PAKET | D1: Micro Cluster | E1: Id Outlet | F1: Nama Outlet | G1: Nama CSO | H1: QTY | I1: Tagihan | J1: Jumlah Pembayaran | K1: Selisih | L1: Keterangan Setoran
A2: 1 | B2: =index!AP3 -> 46204 | C2: =index!AQ3 -> GOL | D2: =index!AR3 -> MC-SAGARANTEN | E2: =index!AS3 -> 17190542 | F2: =index!AT3 -> BERKAH CELLULAR | G2: =index!AU3 -> Muhamad Parhan | H2: =index!AV3 -> 10 | I2: =index!BO3 -> 750000 | J2: =index!BR3 -> 750000 | K2: =index!BT3 -> 0 | L2: =index!BU3 -> 46205
A3: 2 | B3: =index!AP4 -> 46204 | C3: =index!AQ4 -> GOL | D3: =index!AR4 -> MC-SAGARANTEN | E3: =index!AS4 -> 17187147 | F3: =index!AT4 -> Nazila cell | G3: =index!AU4 -> M. Enden Abdul Latif | H3: =index!AV4 -> 5 | I3: =index!BO4 -> 375000 | J3: =index!BR4 -> 375000 | K3: =index!BT4 -> 0 | L3: =index!BU4 -> 46205
A4: 3 | B4: =index!AP5 -> 46204 | C4: =index!AQ5 -> GOL | D4: =index!AR5 -> MC-SAGARANTEN | E4: =index!AS5 -> 1287387 | F4: =index!AT5 -> DEAN CLL | G4: =index!AU5 -> Pebrian Sahri Ramdani | H4: =index!AV5 -> 4 | I4: =index!BO5 -> 300000 | J4: =index!BR5 -> 300000 | K4: =index!BT5 -> 0 | L4: =index!BU5 -> 46205
A5: 4 | B5: =index!AP6 -> 46205 | C5: =index!AQ6 -> GOL | D5: =index!AR6 -> MC-SAGARANTEN | E5: =index!AS6 -> 17288556 | F5: =index!AT6 -> M luthvi Qolbi | G5: =index!AU6 -> M. Enden Abdul Latif | H5: =index!AV6 -> 23 | I5: =index!BO6 -> 1725000 | J5: =index!BR6 -> 1725000 | K5: =index!BT6 -> 0 | L5: =index!BU6 -> 46206
A6: 5 | B6: =index!AP7 -> 46205 | C6: =index!AQ7 -> GOL | D6: =index!AR7 -> MC-SAGARANTEN | E6: =index!AS7 -> 17779453 | F6: =index!AT7 -> ABAY CELL | G6: =index!AU7 -> Muhamad Parhan | H6: =index!AV7 -> 10 | I6: =index!BO7 -> 750000 | J6: =index!BR7 -> 750000 | K6: =index!BT7 -> 0 | L6: =index!BU7 -> 46206
A7: 6 | B7: =index!AP8 -> 46205 | C7: =index!AQ8 -> GOL | D7: =index!AR8 -> MC-SAGARANTEN | E7: =index!AS8 -> 1555825 | F7: =index!AT8 -> SILVI CELL | G7: =index!AU8 -> Pebrian Sahri Ramdani | H7: =index!AV8 -> 7 | I7: =index!BO8 -> 525000 | J7: =index!BR8 -> 525000 | K7: =index!BT8 -> 0 | L7: =index!BU8 -> 46206
A8: 7 | B8: =index!AP9 -> 46207 | C8: =index!AQ9 -> GOL | D8: =index!AR9 -> MC-SAGARANTEN | E8: =index!AS9 -> 17678324 | F8: =index!AT9 -> OJH Celluar | G8: =index!AU9 -> Muhamad Parhan | H8: =index!AV9 -> 6 | I8: =index!BO9 -> 450000 | J8: =index!BR9 -> 450000 | K8: =index!BT9 -> 0 | L8: =index!BU9 -> 46209
A9: 8 | B9: =index!AP10 -> 46207 | C9: =index!AQ10 -> GOL | D9: =index!AR10 -> MC-SAGARANTEN | E9: =index!AS10 -> 17769860 | F9: =index!AT10 -> GIBRAN CELL | G9: =index!AU10 -> Kurnia | H9: =index!AV10 -> 5 | I9: =index!BO10 -> 375000 | J9: =index!BR10 -> 375000 | K9: =index!BT10 -> 0 | L9: =index!BU10 -> 46209
A10: 9 | B10: =index!AP11 -> 46207 | C10: =index!AQ11 -> GOL | D10: =index!AR11 -> MC-SAGARANTEN | E10: =index!AS11 -> 1555825 | F10: =index!AT11 -> SILVI CELL | G10: =index!AU11 -> Pebrian Sahri Ramdani | H10: =index!AV11 -> 7 | I10: =index!BO11 -> 525000 | J10: =index!BR11 -> 525000 | K10: =index!BT11 -> 0 | L10: =index!BU11 -> 46209
A11: 10 | B11: =index!AP12 -> 46209 | C11: =index!AQ12 -> GOL | D11: =index!AR12 -> MC-SAGARANTEN | E11: =index!AS12 -> 1287331 | F11: =index!AT12 -> AKEW CEL | G11: =index!AU12 -> Kurnia | H11: =index!AV12 -> 2 | I11: =index!BO12 -> 150000 | J11: =index!BR12 -> 150000 | K11: =index!BT12 -> 0 | L11: =index!BU12 -> 46210
A12: 11 | B12: =index!AP13 -> 46209 | C12: =index!AQ13 -> GOL | D12: =index!AR13 -> MC-SAGARANTEN | E12: =index!AS13 -> 17792292 | F12: =index!AT13 -> Gilang cell 6 | G12: =index!AU13 -> Pebrian Sahri Ramdani | H12: =index!AV13 -> 9 | I12: =index!BO13 -> 675000 | J12: =index!BR13 -> 675000 | K12: =index!BT13 -> 0 | L12: =index!BU13 -> 46210
A13: 12 | B13: =index!AP14 -> 46210 | C13: =index!AQ14 -> GOL | D13: =index!AR14 -> MC-SAGARANTEN | E13: =index!AS14 -> 17253568 | F13: =index!AT14 -> AHZACELL | G13: =index!AU14 -> Kurnia | H13: =index!AV14 -> 2 | I13: =index!BO14 -> 150000 | J13: =index!BR14 -> 150000 | K13: =index!BT14 -> 0 | L13: =index!BU14 -> 46211
... A250: 249 | B250: =index!AP251 -> 0 | C250: =index!AQ251 -> 0 | D250: =index!AR251 | E250: =index!AS251 -> 0 | F250: =index!AT251 -> #N/A | G250: =index!AU251 -> 0 | H250: =index!AV251 -> 0 | I250: =index!BO251 -> 0 | J250: =index!BR251 -> 0 | K250: =index!BT251 -> 0 | L250: =index!BU251 -> 0

Sheet penjualan-direct-selling
A1: ID DSE | B1: Nama CSO | C1: SP 3GB | D1: Pengambilan | E1: Pembayaran | F1: PCS | G1: GAP | H1: TOTAL
A2: SKBPLARA04 | B2: Muhamad Parhan | C2: =index!AG12 -> 125 | D2: =index!AH12 -> 1875000 | E2: =index!AI12 -> 3285000 | F2: =index!AJ12 -> 125 | G2: =index!AK12 -> 0 | H2: =index!AL12 -> 125
A3: SKBPLARA08 | B3: Andi Sutiawan | C3: =index!AG13 -> 313 | D3: =index!AH13 -> 4695000 | E3: =index!AI13 -> 5775000 | F3: =index!AJ13 -> 313 | G3: =index!AK13 -> 0 | H3: =index!AL13 -> 313
A4: SKBPLARA11 | B4: M. Enden Abdul Latif | C4: =index!AG14 -> 150 | D4: =index!AH14 -> 2250000 | E4: =index!AI14 -> 1500000 | F4: =index!AJ14 -> 150 | G4: =index!AK14 -> 0 | H4: =index!AL14 -> 150
A5: DSESGRN01 | B5: Pebrian Sahri Ramdani | C5: =index!AG15 -> 100 | D5: =index!AH15 -> 1500000 | E5: =index!AI15 -> 4920000 | F5: =index!AJ15 -> 100 | G5: =index!AK15 -> 0 | H5: =index!AL15 -> 100
C6: =SUM(C2:C5) -> 688 | D6: =SUM(D2:D5) -> 10320000 | E6: =SUM(E2:E5) -> 15480000 | F6: =SUM(F2:F5) -> 688 | G6: =SUM(G2:G5) -> 0 | H6: =SUM(H2:H5) -> 688

Sheet penjualan-hifi
A1: No | B1: Barang | C1: Jumlah | D1: Nomor Hifi | E1: ICCID | F1: IMEI Devices | G1: Nama | H1: Harga | I1: Tgl Ambil | J1: Tgl Bayar | K1: Keterangan | L1: Tgl Repot
A2: 1 | B2: =index!BZ3 -> HIFI IM3 | C2: =index!CA3 -> 1 | D2: =index!CB3 -> 085882767329 | E2: =index!CC3 -> 89620100002033537644 | F2: =index!CD3 -> 355806671137009 | G2: =index!CE3 -> PARHAN | H2: =index!CF3 -> 310000 | I2: =index!CG3 -> 46185 | ... L2: =index!CJ3 -> 0
A3: 2 | B3: =index!BZ4 -> HIFI IM3 | C3: =index!CA4 -> 1 | D3: =index!CB4 -> 085882767330 | E3: =index!CC4 -> 89620100002033537651 | F3: =index!CD4 -> 355806671137223 | G3: =index!CE4 -> ANDI | H3: =index!CF4 -> 0 | I3: =index!CG4 -> 46185 | ... L3: =index!CJ4 -> 0
A4: 3 | B4: =index!BZ5 -> HIFI IM3 | C4: =index!CA5 -> 1 | D4: =index!CB5 -> 085882767331 | E4: =index!CC5 -> 89620100002033537652 | F4: =index!CD5 -> 355806671159425 | G4: =index!CE5 -> ENDEN | H4: =index!CF5 -> 310000 | I4: =index!CG5 -> 46185 | ... L4: =index!CJ5 -> 0
A5: 4 | B5: =index!BZ6 -> HIFI IM3 | C5: =index!CA6 -> 1 | D5: =index!CB6 -> 085882767332 | E5: =index!CC6 -> 89620100002033537677 | F5: =index!CD6 -> 355806671159581 | G5: =index!CE6 -> PEBRIAN | H5: =index!CF6 -> 0 | I5: =index!CG6 -> 46185 | ... L5: =index!CJ6 -> 0
A6: 5 | B6: =index!BZ7 -> HIFI IM3 | C6: =index!CA7 -> 1 | D6: =index!CB7 -> 085882768254 | E6: =index!CC7 -> 89620100002033543817 | F6: =index!CD7 -> 355806671162734 | G6: =index!CE7 -> PARHAN | H6: =index!CF7 -> 310000 | I6: =index!CG7 -> 46197 | ... L6: =index!CJ7 -> 0
A7: 6 | B7: =index!BZ8 -> HIFI IM3 | C7: =index!CA8 -> 1 | D7: =index!CB8 -> 085882768256 | E7: =index!CC8 -> 89620100002033543833 | F7: =index!CD8 -> 355806671166644 | G7: =index!CE8 -> ANDI | H7: =index!CF8 -> 0 | I7: =index!CG8 -> 46197 | ... L7: =index!CJ8 -> 0
A8: 7 | B8: =index!BZ9 -> HIFI IM3 | C8: =index!CA9 -> 1 | D8: =index!CB9 -> 085882768385 | E8: =index!CC9 -> 89620100002033544741 | F8: =index!CD9 -> 355806671205749 | G8: =index!CE9 -> ENDEN | H8: =index!CF9 -> 310000 | I8: =index!CG9 -> 46197 | ... L8: =index!CJ9 -> 0
A9: 8 | B9: =index!BZ10 -> HIFI IM3 | C9: =index!CA10 -> 1 | D9: =index!CB10 -> 085882768387 | E9: =index!CC10 -> 89620100002033544766 | F9: =index!CD10 -> 355806671170737 | G9: =index!CE10 -> PEBRIAN | H9: =index!CF10 -> 0 | I9: =index!CG10 -> 46197 | ... L9: =index!CJ10 -> 0
A10: 9 | B10: =index!BZ11 -> HIFI IM3 | C10: =index!CA11 -> 1 | D10: =index!CB11 -> 085882767231 | E10: =index!CC11 -> 89620100002033537141 | F10: =index!CD11 -> 355806671183334 | G10: =index!CE11 -> PAK VIJE | H10: =index!CF11 -> 0 | I10: =index!CG11 -> 46198 | ... L10: =index!CJ11 -> 0
A11: 10 | B11: =index!BZ12 -> HIFI IM3 | C11: =index!CA12 -> 1 | D11: =index!CB12 -> 085882767236 | E11: =index!CC12 -> 89620100002033537174 | F11: =index!CD12 -> 355806671220904 | G11: =index!CE12 -> PAK VIJE | H11: =index!CF12 -> 0 | I11: =index!CG12 -> 46203 | ... L11: =index!CJ12 -> 0
A12: 11 | B12: =index!BZ13 -> HIFI 3ID | C12: =index!CA13 -> 1 | D12: =index!CB13 -> 0895613208575 | E12: =index!CC13 -> 8962893000244846652 | F12: =index!CD13 -> 355806671150283 | G12: =index!CE13 -> 0 | H12: =index!CF13 -> 0 | I12: =index!CG13 -> 0 | ... L12: =index!CJ13 -> 0
A13: 12 | B13: =index!BZ14 -> HIFI 3ID | C13: =index!CA14 -> 1 | D13: =index!CB14 -> 0895613208576 | E13: =index!CC14 -> 8962893000244846653 | F13: =index!CD14 -> 355806671150689 | G13: =index!CE14 -> 0 | H13: =index!CF14 -> 0 | I13: =index!CG14 -> 0 | ... L13: =index!CJ14 -> 0
... A15: 14 | B15: =index!BZ16 -> HIFI 3ID | C15: =index!CA16 -> 1 | D15: =index!CB16 -> 0895613208578 | E15: =index!CC16 -> 8962893000244846655 | F15: =index!CD16 -> 355806671150630 | G15: =index!CE16 -> 0 | H15: =index!CF16 -> 0 | I15: =index!CG16 -> 0 | ... L15: =index!CJ16 -> 0
A16: 15 | G16: =index!CE17 -> 0 | H16: =index!CF17 -> 0 | I16: =index!CG17 -> 0 | J16: =index!CH17 -> 0 | K16: =index!CI17 -> STOK GUDANG | L16: =index!CJ17 -> 0
A17: 16 | G17: =index!CE18 -> 0 | H17: =index!CF18 -> 0 | I17: =index!CG18 -> 0 | J17: =index!CH18 -> 0 | K17: =index!CI18 -> STOK GUDANG | L17: =index!CJ18 -> 0

Sheet Dashboard
A1: TOTAL PENJUALAN SALMO | B1: SP DAN VOUCHER | C1: ALL PAKET | D1: HIFI
A2: ='penjualan-salmo'!B6 -> 178509000 | B2: ='penjualan-reguler-new'!N7+'penjualan-reguler-new'!N23 -> 75448200 | C2: =SUM('penjualan-paket-jupiter'!J2:J400)+'penjualan-direct-selling'!E6 -> 30405000 | D2: =SUM('penjualan-hifi'!H2:H17) -> 1240000

Sheet index
A1: stok gudang | F1: stok dse | N1: salmo | Q1: penjualan | AO1: paket jupiter | CL1: PENJUALAN FISIK SAGARANTEN
A2: nama barang | B2: segel | C2: sellin | D2: total stok | F2: STOCK AKHIR CSO SAGARANTEN | N2: Nama cso | O2: Amount | Q2: JENIS BARANG | R2: 19 Jun | S2: 1 | T2: 19 Jun | U2: 2 | V2: 19 Jun | W2: 3 | X2: 19 Jun | Y2: 4 | Z2: Total 19 Jun | AA2: Total Penjualan | AB2: HARGA | AC2: JUMLAH | AE2: Nama CSO | AO2: No. | AP2: Tanggal Pengambilan | AQ2: PAKET | AR2: Micro Cluster | AS2: Id Outlet | AT2: Nama Outlet | AU2: Nama CSO | AV2: QTY | AW2: SP ZERO | AX2: SP 3GB | AY2: SP 6GB | AZ2: SP 9GB | BA2: VDK | BB2: V 1 GB | BC2: V 2.5 GB | BD2: V 3 GB | BE2: V 3.5 GB | BF2: V 5 GB | BG2: V 7GB | BH2: V 6GB | BI2: V 1.5 GB | BJ2: V 3GB 1 | BK2: VCR 3GB 3 | BL2: VCR 5GB 2 | BM2: VCR 5GB 3 | BN2: SP 10GB | BO2: Tagihan | BP2: Tanggal Pembayaran | BQ2: Qty | BR2: Jumlah Pembayaran | BS2: Metode Pembayaran | BT2: Selisih | BU2: Keterangan Setoran | BV2: SALDO | BW2: GAP | BY2: No | BZ2: Barang | CA2: Jumlah | CB2: Nomor Hifi | CC2: ICCID | CD2: IMEI Devices | CE2: Nama | CF2: Harga | CG2: Tgl Ambil | CH2: Tgl Bayar | CI2: Keterangan | CJ2: Tgl Repot | DF2: Weekly | DG2: Andi | DL2: Parhan | DQ2: Enden | DV2: Pebrian
N3: Parhan | O3: =29759000+O9 -> 32259000 | S3: Andi | U3: Parhan | W3: Enden | Y3: Pebrian | AF3: SP 3GB injek | AG3: SP 3GB | AH3: V 3GB 14H | AI3: V 2.5 GB | AJ3: V 3.5 GB | AK3: V 1.5 GB | AL3: VCR 5GB 3 | AM3: SP 10GB | AO3: 1 | AP3: 46204 | AQ3: GOL | AR3: MC-SAGARANTEN | AS3: 17190542 | AT3: BERKAH CELLULAR | AU3: Muhamad Parhan | AV3: 10 | AW3: 0 | AX3: 30 | AY3: 0 | AZ3: 0 | BA3: 0 | BB3: 0 | BC3: 0 | BD3: 0 | BE3: 0 | BF3: 0 | BG3: 0 | BH3: 0 | BI3: 0 | BJ3: 0 | BK3: 0 | BL3: 0 | BM3: 0 | BN3: 10 | BO3: 750000 | BP3: 46204 | BQ3: 10 | BR3: 750000 | BS3: CASH | BT3: 0 | BU3: 46205 | BV3: 200000 | BY3: 1 | BZ3: HIFI IM3 | CA3: 1 | CB3: 085882767329 | CC3: 89620100002033537644 | CD3: 355806671137009 | CE3: PARHAN | CF3: 310000 | CG3: 46185 | CH3: 46212 | CI3: LUNAS | CL3: =TODAY()-1 -> 46246 | CV3: Nama Barang | CW3: Andi | CX3: Parhan | CY3: Enden | CZ3: Pebrian | DA3: Spv | DB3: Total Penjualan | DC3: Harga | DD3: Amount | DF3: Nama Barang | DG3: w1 | DH3: w2 | DI3: w3 | DJ3: w4 | DK3: Total | DL3: w1 | DM3: w2 | DN3: w3 | DO3: w4 | DP3: Total | DQ3: w1 | DR3: w2 | DS3: w3 | DT3: w4 | DU3: Total | DV3: w1 | DW3: w2 | DX3: w3 | DY3: w4 | DZ3: Total | EA3: Total Weekly | EB3: Harga | EC3: Amount
A4: SP ZERO | B4: 100 | C4: 0 | D4: =C4+B4 -> 100 | F4: JENIS BARANG | G4: ANDI | H4: FARHAN | I4: ENDEN | J4: PEBRIAN | K4: SPV | L4: TOTAL | N4: Andi Setiawan | O4: =45713000+O10 -> 52263000 | Q4: SP ZERO | R4: =CM6 -> 0 | S4: =CW4 -> 0 | T4: =CN6 -> 0 | U4: =CX4 -> 0 | V4: =CO6 -> 0 | W4: =CY4 -> 0 | X4: =CP6 -> 0 | Y4: =CZ4 -> 0 | Z4: =R4+T4+V4+X4 -> 0 | AA4: =S4+U4+W4+Y4 -> 0 | AB4: 11000 | AC4: =AA4*AB4 -> 0 | AE4: Muhamad Parhan | AF4: =GETPIVOTDATA("Sum of Qty2",$R$36,"Nama CSO","Muhamad Parhan")+GETPIVOTDATA("SP 3GB",$AI$70,"Nama CSO","Muhamad Parhan") -> 219 | AG4: =E31 -> 162 | AH4: =H31 -> 27 | AI4: =I31 -> 129 | AJ4: =K31 -> 33 | AK4: =O31 -> 135 | AL4: =S31 -> 0 | AM4: =T31 -> 31 | AO4: 2 | AP4: 46204 | AQ4: GOL | AR4: MC-SAGARANTEN | AS4: 17187147 | AT4: Nazila cell | AU4: M. Enden Abdul Latif | AV4: 5 | AW4: 0 | AX4: 15 | AY4: 0 | AZ4: 0 | BA4: 0 | BB4: 0 | BC4: 0 | BD4: 0 | BE4: 0 | BF4: 0 | BG4: 0 | BH4: 0 | BI4: 0 | BJ4: 0 | BK4: 0 | BL4: 0 | BM4: 0 | BN4: 5 | BO4: 375000 | BP4: 46204 | BQ4: 5 | BR4: 375000 | BS4: CASH | BT4: 0 | BU4: 46205 | BV4: 1150000 | BY4: 2 | BZ4: HIFI IM3 | CA4: 1 | CB4: 085882767330 | CC4: 89620100002033537651 | CD4: 355806671137223 | CE4: ANDI | CG4: 46185 | CI4: ON HAND DSE | CL4: JENIS BARANG | CM4: 1 | CN4: 2 | CO4: 3 | CP4: 4 | CQ4: 5 | CR4: TOTAL PENJUALAN | CS4: HARGA | CT4: JUMLAH | CV4: SP ZERO | CW4: 0 | CX4: 0 | CY4: 0 | CZ4: 0 | DB4: 35 | DC4: 11000 | DD4: 385000 | DF4: SP ZERO | DG4: 0 | DH4: 0 | DI4: 0 | DJ4: 0 | DK4: 0 | DL4: 0 | DM4: 0 | DN4: 0 | DO4: 0 | DP4: 0 | DQ4: 0 | DR4: 0 | DS4: 0 | DT4: 0 | DU4: 0 | DV4: 0 | DW4: 0 | DX4: 0 | DY4: 0 | DZ4: 0 | EA4: 49 | EB4: 11000 | EC4: 539000
A5: SP 3GB injek | B5: 4413 | C5: 15 | D5: =C5+B5 -> 4428 | F5: SP ZERO | G5: 86 | H5: 80 | I5: 96 | J5: 100 | K5: 22 | L5: =SUM(G5:K5) -> 384 | N5: M. Enden Abdul Latif | O5: =38942000+O11 -> 43042000 | Q5: SP 3GB INJEK | R5: =CM7+AF20 -> 0 | S5: =CW5+AF5-25 -> 364 | T5: =CN7+AF19 -> 0 | U5: =CX5+AF4-25 -> 255 | V5: =CO7+AF21 -> 0 | W5: =CY5+AF6 -> 339 | X5: =CP7+AF22 -> 0 | Y5: =CZ5+AF7+-25 -> 303 | Z5: =R5+T5+V5+X5 -> 0 | AA5: =S5+U5+W5+Y5 -> 1261 | AB5: 30000 | AC5: =AA5*AB5 -> 37830000 | AE5: Andi Sutiawan | AF5: =GETPIVOTDATA("Sum of Qty2",$R$36,"Nama CSO","Andi Sutiawan")+GETPIVOTDATA("SP 3GB",$AI$70,"Nama CSO","Andi Sutiawan") -> 385 | AG5: =E32 -> 114 | AH5: =H32 -> 0 | AI5: =I32 -> 87 | AJ5: =K32 -> 27 | AK5: =O32 -> 114 | AL5: =S32 -> 0 | AM5: =T32 -> 24 | AO5: 3 | AP5: 46204 | AQ5: GOL | AR5: MC-SAGARANTEN | AS5: 1287387 | AT5: DEAN CLL | AU5: Pebrian Sahri Ramdani | AV5: 4 | AW5: 0 | AX5: 12 | AY5: 0 | AZ5: 0 | BA5: 0 | BB5: 0 | BC5: 0 | BD5: 0 | BE5: 0 | BF5: 0 | BG5: 0 | BH5: 0 | BI5: 0 | BJ5: 0 | BK5: 0 | BL5: 0 | BM5: 0 | BN5: 4 | BO5: 300000 | BP5: 46204 | BQ5: 4 | BR5: 300000 | BS5: CASH | BT5: 0 | BU5: 46205 | BV5: 2200000 | BY5: 3 | BZ5: HIFI IM3 | CA5: 1 | CB5: 085882767331 | CC5: 89620100002033537652 | CD5: 355806671159425 | CE5: ENDEN | CF5: 310000 | CG5: 46185 | CH5: 46205 | CI5: LUNAS | CM5: ANDI | CN5: FARHAN | CO5: ENDEN | CP5: PEBRIAN | CQ5: SPV | CV5: SP 3GB INJEK | CW5: 4 | CX5: 61 | CY5: 90 | CZ5: 0 | DB5: 0 | DC5: 30000 | DD5: 0 | DF5: SP 3GB INJEK | DG5: 0 | DH5: 4 | DI5: 0 | DJ5: 0 | DK5: 4 | DL5: 42 | DM5: 19 | DN5: 0 | DO5: 0 | DP5: 61 | DQ5: 80 | DR5: 10 | DS5: 0 | DT5: 0 | DU5: 90 | DV5: 0 | DW5: 0 | DX5: 0 | DY5: 0 | DZ5: 0 | EA5: 0 | EB5: 30000 | EC5: 0
A6: SP 3GB ori | B6: 70 | C6: 8 | D6: =C6+B6 -> 78 | F6: SP 3GB INJEK | G6: 122 | H6: 64 | I6: 48 | J6: 59 | K6: 0 | L6: =SUM(G6:K6) -> 293 | N6: Pebrian Sahri Ramdani | O6: =47595000+O12 -> 50945000 | Q6: SP 3GB ORI | R6: =CM8+AG20 -> 0 | S6: =CW6+AG5 -> 119 | T6: =CN8+AG19 -> 0 | U6: =CX6+AG4 -> 166 | V6: =CO8+AG21 -> 0 | W6: =CY6+AG6 -> 126 | X6: =CP8+AG22 -> 0 | Y6: =CZ6+AG7 -> 63 | Z6: =R6+T6+V6+X6 -> 0 | AA6: =S6+U6+W6+Y6 -> 474 | AB6: 25000 | AC6: =AA6*AB6 -> 11850000 | AE6: M. Enden Abdul Latif | AF6: =GETPIVOTDATA("Sum of Qty2",$R$36,"Nama CSO","M. Enden Abdul Latif")+GETPIVOTDATA("SP 3GB",$AI$70,"Nama CSO","M. Enden Abdul Latif") -> 249 | AG6: =E33 -> 126 | AH6: =H33 -> 21 | AI6: =I33 -> 45 | AJ6: =K33 -> 81 | AK6: =O33 -> 105 | AL6: =S33 -> 0 | AM6: =T33 -> 33 | AO6: 4 | AP6: 46205 | AQ6: GOL | AR6: MC-SAGARANTEN | AS6: 17288556 | AT6: M luthvi Qolbi | AU6: M. Enden Abdul Latif | AV6: 23 | AW6: 0 | AX6: 69 | AY6: 0 | AZ6: 0 | BA6: 0 | BB6: 0 | BC6: 0 | BD6: 0 | BE6: 0 | BF6: 0 | BG6: 0 | BH6: 0 | BI6: 0 | BJ6: 0 | BK6: 0 | BL6: 0 | BM6: 0 | BN6: 23 | BO6: 1725000 | BP6: 46205 | BQ6: 23 | BR6: 1725000 | BS6: CASH | BT6: 0 | BU6: 46206 | BV6: 3000000 | BY6: 4 | BZ6: HIFI IM3 | CA6: 1 | CB6: 085882767332 | CC6: 89620100002033537677 | CD6: 355806671159581 | CE6: PEBRIAN | CG6: 46185 | CI6: ON HAND DSE | CL6: SP ZERO | CM6: 0 | CN6: 0 | CO6: 0 | CP6: 0 | CQ6: 0 | CR6: - | CS6: 11000 | CT6: - | CV6: SP 3GB ORI | CW6: 5 | CX6: 4 | CY6: 0 | CZ6: 0 | DB6: 581 | DC6: 25000 | DD6: 14525000 | DF6: SP 3GB ORI | DG6: 0 | DH6: 5 | DI6: 0 | DJ6: 0 | DK6: 5 | DL6: 0 | DM6: 4 | DN6: 0 | DO6: 0 | DP6: 4 | DQ6: 0 | DR6: 0 | DS6: 0 | DT6: 0 | DU6: 0 | DV6: 0 | DW6: 0 | DX6: 0 | DY6: 0 | DZ6: 0 | EA6: 672 | EB6: 25000 | EC6: 16800000
A7: SP 9GB | B7: 0 | C7: 0 | D7: =C7+B7 -> 0 | F7: SP 3GB ORI | G7: 0 | H7: 63 | I7: 90 | J7: 183 | K7: 10 | L7: =SUM(G7:K7) -> 346 | N7: Grand Total | O7: =SUM(O3:O6) -> 178509000 | Q7: SP 9GB | R7: =CM9 -> 0 | S7: =CW7 -> 0 | T7: =CN9 -> 0 | U7: =CX7 -> 5 | V7: =CO9 -> 0 | W7: =CY7 -> 5 | X7: =CP9 -> 0 | Y7: =CZ7 -> 0 | Z7: =R7+T7+V7+X7 -> 0 | AA7: =S7+U7+W7+Y7 -> 10 | AB7: 40000 | AC7: =AA7*AB7 -> 400000 | AE7: Pebrian Sahri Ramdani | AF7: =GETPIVOTDATA("Sum of Qty2",$R$36,"Nama CSO","Pebrian Sahri Ramdani")+GETPIVOTDATA("SP 3GB",$AI$70,"Nama CSO","Pebrian Sahri Ramdani") -> 328 | AG7: =E34 -> 63 | AH7: =H34 -> 0 | AI7: =I34 -> 12 | AJ7: =K34 -> 51 | AK7: =O34 -> 63 | AL7: =S34 -> 0 | AM7: =T34 -> 76 | AO7: 5 | AP7: 46205 | AQ7: GOL | AR7: MC-SAGARANTEN | AS7: 17779453 | AT7: ABAY CELL | AU7: Muhamad Parhan | AV7: 10 | AW7: 0 | AX7: 30 | AY7: 0 | AZ7: 0 | BA7: 0 | BB7: 0 | BC7: 0 | BD7: 0 | BE7: 0 | BF7: 0 | BG7: 0 | BH7: 0 | BI7: 0 | BJ7: 0 | BK7: 0 | BL7: 0 | BM7: 0 | BN7: 10 | BO7: 750000 | BP7: 46205 | BQ7: 10 | BR7: 750000 | BS7: CASH | BT7: 0 | BU7: 46206 | BV7: 500000 | BY7: 5 | BZ7: HIFI IM3 | CA7: 1 | CB7: 085882768254 | CC7: 89620100002033543817 | CD7: 355806671162734 | CE7: PARHAN | CF7: 310000 | CG7: 46197 | CH7: 46212 | CI7: LUNAS | CL7: SP 3GB INJEK | CM7: 0 | CN7: 0 | CO7: 0 | CP7: 0 | CQ7: 0 | CR7: - | CS7: 30000 | CT7: - | CV7: SP 9GB | CW7: 0 | CX7: 5 | CY7: 5 | CZ7: 0 | DB7: 0 | DC7: 30000 | DD7: 0 | DF7: SP 9GB | DG7: 0 | DH7: 0 | DI7: 0 | DJ7: 0 | DK7: 0 | DL7: 0 | DM7: 5 | DN7: 0 | DO7: 0 | DP7: 5 | DQ7: 5 | DR7: 0 | DS7: 0 | DT7: 0 | DU7: 5 | DV7: 0 | DW7: 0 | DX7: 0 | DY7: 0 | DZ7: 0 | EA7: 0 | EB7: 40000 | EC7: 0
A8: SP 10GB | B8: 746 | C8: 0 | D8: =C8+B8 -> 746 | F8: SP 9GB | G8: 0 | H8: 0 | I8: 0 | J8: 5 | K8: 0 | L8: =SUM(G8:K8) -> 5 | Q8: SP 10GB | R8: =CM10 -> 0 | S8: =AM5 -> 24 | T8: =CN10 -> 0 | U8: =AM4 -> 31 | V8: =CO10 -> 0 | W8: =AM6 -> 33 | X8: =CP10 -> 0 | Y8: =AM7 -> 76 | Z8: =R8+T8+V8+X8 -> 0 | AA8: =S8+U8+W8+Y8 -> 164 | AC8: =AA8*AB8 -> 0 | AF8: 200 | AG8: 348 | AH8: 48 | AI8: 219 | AJ8: 129 | AK8: 300 | AL8: 300 | AM8: 300 | AO8: 6 | AP8: 46205 | AQ8: GOL | AR8: MC-SAGARANTEN | AS8: 1555825 | AT8: SILVI CELL | AU8: Pebrian Sahri Ramdani | AV8: 7 | AW8: 0 | AX8: 21 | AY8: 0 | AZ8: 0 | BA8: 0 | BB8: 0 | BC8: 0 | BD8: 0 | BE8: 0 | BF8: 0 | BG8: 0 | BH8: 0 | BI8: 0 | BJ8: 0 | BK8: 0 | BL8: 0 | BM8: 0 | BN8: 7 | BO8: 525000 | BP8: 46205 | BQ8: 7 | BR8: 525000 | BS8: CASH | BT8: 0 | BU8: 46206 | BV8: 200000 | BY8: 6 | BZ8: HIFI IM3 | CA8: 1 | CB8: 085882768256 | CC8: 89620100002033543833 | CD8: 355806671166644 | CE8: ANDI | CG8: 46197 | CI8: ON HAND DSE | CL8: SP 3GB ORI | CM8: 0 | CN8: 0 | CO8: 0 | CP8: 0 | CQ8: 0 | CR8: 75 | CS8: 25000 | CT8: 1875000 | CV8: SP 10GB | CW8: 0 | CX8: 0 | CY8: 0 | CZ8: 0 | DB8: 0 | DD8: 0 | DF8: SP 10GB | DG8: 0 | DH8: 0 | DI8: 0 | DJ8: 0 | DK8: 0 | DL8: 0 | DM8: 0 | DN8: 0 | DO8: 0 | DP8: 0 | DQ8: 0 | DR8: 0 | DS8: 0 | DT8: 0 | DU8: 0 | DV8: 0 | DW8: 0 | DX8: 0 | DY8: 0 | DZ8: 0 | EA8: 0 | EB8: 40000 | EC8: 0
B9: 0 | C9: 0 | D9: =C9+B9 -> 0 | G9: 0 | H9: 0 | I9: 0 | J9: 0 | K9: 0 | L9: =SUM(G9:K9) -> 0 | O9: 2500000 | R9: =CM11 -> 0 | S9: =CW9 -> 9 | T9: =CN11 -> 0 | U9: =CX9 -> 65 | V9: =CO11 -> 0 | W9: =CY9 -> 90 | X9: =CP11 -> 0 | Y9: =CZ9 -> 0 | Z9: =R9+T9+V9+X9 -> 0 | AA9: =S9+U9+W9+Y9 -> 164 | AC9: =AA9*AB9 -> 0 | AO9: 7 | AP9: 46207 | AQ9: GOL | AR9: MC-SAGARANTEN | AS9: 17678324 | AT9: OJH Celluar | AU9: Muhamad Parhan | AV9: 6 | AW9: 0 | AX9: 18 | AY9: 0 | AZ9: 0 | BA9: 0 | BB9: 0 | BC9: 0 | BD9: 0 | BE9: 0 | BF9: 0 | BG9: 0 | BH9: 0 | BI9: 0 | BJ9: 0 | BK9: 0 | BL9: 0 | BM9: 0 | BN9: 6 | BO9: 450000 | BP9: 46207 | BQ9: 6 | BR9: 450000 | BS9: CASH | BT9: 0 | BU9: 46209 | BV9: 800000 | BY9: 7 | BZ9: HIFI IM3 | CA9: 1 | CB9: 085882768385 | CC9: 89620100002033544741 | CD9: 355806671205749 | CE9: ENDEN | CF9: 310000 | CG9: 46197 | CH9: 46205 | CI9: LUNAS | CL9: SP 9GB | CM9: 0 | CN9: 0 | CO9: 0 | CP9: 0 | CQ9: 0 | CR9: - | CS9: 40000 | CT9: - | CW9: 9 | CX9: 65 | CY9: 90 | CZ9: 0 | DB9: 0 | DD9: 0 | DF9: Total SP | DG9: 0 | DH9: 0 | DI9: 0 | DJ9: 0 | DK9: 9 | DL9: 0 | DM9: 0 | DN9: 0 | DO9: 0 | DP9: 70 | DQ9: 0 | DR9: 0 | DS9: 0 | DT9: 0 | DU9: 95 | DV9: 0 | DW9: 0 | DX9: 0 | DY9: 0 | DZ9: 0 | EA9: 721 | EC9: 17339000
A10: VDK | B10: 7649 | C10: 0 | D10: =C10+B10 -> 7649 | G10: 0 | H10: 0 | I10: 0 | J10: 0 | K10: 0 | L10: =SUM(G10:K10) -> 0 | O10: 6550000 | Q10: VDK | R10: =CM12 -> 0 | S10: =CW10 -> 238 | T10: =CN12 -> 0 | U10: =CX10 -> 600 | V10: =CO12 -> 0 | W10: =CY10 -> 189 | X10: =CP12 -> 0 | Y10: =CZ10 -> 600 | Z10: =R10+T10+V10+X10 -> 0 | AA10: =S10+U10+W10+Y10 -> 1627 | AB10: 600 | AC10: =AA10*AB10 -> 976200 | AE10: direct selling | AO10: 8 | AP10: 46207 | AQ10: GOL | AR10: MC-SAGARANTEN | AS10: 17769860 | AT10: GIBRAN CELL | AU10: Kurnia | AV10: 5 | AW10: 0 | AX10: 15 | AY10: 0 | AZ10: 0 | BA10: 0 | BB10: 0 | BC10: 0 | BD10: 0 | BE10: 0 | BF10: 0 | BG10: 0 | BH10: 0 | BI10: 0 | BJ10: 0 | BK10: 0 | BL10: 0 | BM10: 0 | BN10: 5 | BO10: 375000 | BP10: 46207 | BQ10: 5 | BR10: 375000 | BS10: CASH | BT10: 0 | BU10: 46209 | BV10: 800000 | BY10: 8 | BZ10: HIFI IM3 | CA10: 1 | CB10: 085882768387 | CC10: 89620100002033544766 | CD10: 355806671170737 | CE10: PEBRIAN | CG10: 46197 | CI10: ON HAND DSE | CL10: SP 10GB | CR10: - | CT10: - | CV10: VDK | CW10: 238 | CX10: 600 | CY10: 189 | CZ10: 600 | DB10: 70 | DC10: 600 | DD10: 42000 | EC10: 0
A11: 3GB/14HR | B11: 0 | C11: 97 | D11: =C11+B11 -> 97 | F11: VDK | G11: 100 | H11: 300 | I11: 44 | J11: 150 | K11: 0 | L11: =SUM(G11:K11) -> 594 | O11: 4100000 | Q11: Voucher 3GB 14HR | R11: =CM13+AH20 -> 0 | S11: =CW11+AH5 -> 0 | T11: =CN13+AH19 -> 0 | U11: =CX11+AH4 -> 27 | V11: =CO13+AH21 -> 0 | W11: =CY11+AH6 -> 25 | X11: =CP13+AH22 -> 0 | Y11: =CZ11+AH7 -> 4 | Z11: =R11+T11+V11+X11 -> 0 | AA11: =S11+U11+W11+Y11 -> 56 | AB11: 22500 | AC11: =AA11*AB11 -> 1260000 | AE11: ID DSE | AF11: Nama CSO | AG11: SP 3GB | AH11: Pengambilan | AI11: Pembayaran | AJ11: PCS | AK11: GAP | AL11: TOTAL | AO11: 9 | AP11: 46207 | AQ11: GOL | AR11: MC-SAGARANTEN | AS11: 1555825 | AT11: SILVI CELL | AU11: Pebrian Sahri Ramdani | AV11: 7 | AW11: 0 | AX11: 21 | AY11: 0 | AZ11: 0 | BA11: 0 | BB11: 0 | BC11: 0 | BD11: 0 | BE11: 0 | BF11: 0 | BG11: 0 | BH11: 0 | BI11: 0 | BJ11: 0 | BK11: 0 | BL11: 0 | BM11: 0 | BN11: 7 | BO11: 525000 | BP11: 46207 | BQ11: 7 | BR11: 525000 | BS11: CASH | BT11: 0 | BU11: 46209 | BV11: 200000 | BY11: 9 | BZ11: HIFI IM3 | CA11: 1 | CB11: 085882767231 | CC11: 89620100002033537141 | CD11: 355806671183334 | CE11: PAK VIJE | CG11: 46198 | CI11: ON HAND DSE | CR11: - | CT11: - | CV11: Voucher 3GB 14HR | CW11: 0 | CX11: 0 | CY11: 4 | CZ11: 4 | DB11: 0 | DC11: 22500 | DD11: 0 | DF11: VOUCHER
A12: 2,5GB | B12: 300 | C12: 815 | D12: =C12+B12 -> 1115 | F12: Voucher 3GB 14HR | G12: 0 | H12: 0 | I12: 0 | J12: 0 | K12: 0 | L12: =SUM(G12:K12) -> 0 | O12: 3350000 | Q12: Voucher 2,5GB | R12: =CM14+AI20 -> 0 | S12: =CW12+AI5 -> 99 | T12: =CN14+AI19 -> 0 | U12: =CX12+AI4 -> 245 | V12: =CO14+AI21 -> 3 | W12: =CY12+AI6 -> 131 | X12: =CP14+AI22 -> 0 | Y12: =CZ12+AI7 -> 22 | Z12: =R12+T12+V12+X12 -> 3 | AA12: =S12+U12+W12+Y12 -> 497 | AB12: 13500 | AC12: =AA12*AB12 -> 6709500 | AE12: SKBPLARA04 | AF12: Muhamad Parhan | AG12: =GETPIVOTDATA("Sum of QTY",$R$36,"Nama CSO","Muhamad Parhan") -> 125 | AH12: =15000*AG12 -> 1875000 | AI12: =AF4*15000 -> 3285000 | AJ12: =GETPIVOTDATA("Sum of Qty2",$R$36,"Nama CSO","Muhamad Parhan")-1 -> 125 | AK12: =AG12-AJ12 -> 0 | AL12: =AJ12+AK12 -> 125 | AO12: 10 | AP12: 46209 | AQ12: GOL | AR12: MC-SAGARANTEN | AS12: 1287331 | AT12: AKEW CEL | AU12: Kurnia | AV12: 2 | AW12: 0 | AX12: 6 | AY12: 0 | AZ12: 0 | BA12: 0 | BB12: 0 | BC12: 0 | BD12: 0 | BE12: 0 | BF12: 0 | BG12: 0 | BH12: 0 | BI12: 0 | BJ12: 0 | BK12: 0 | BL12: 0 | BM12: 0 | BN12: 2 | BO12: 150000 | BP12: 46209 | BQ12: 2 | BR12: 150000 | BS12: CASH | BT12: 0 | BU12: 46210 | BV12: 2600000 | BY12: 10 | BZ12: HIFI IM3 | CA12: 1 | CB12: 085882767236 | CC12: 89620100002033537174 | CD12: 355806671220904 | CE12: PAK VIJE | CG12: 46203 | CI12: STOK GUDANG | CL12: VDK | CM12: 0 | CN12: 0 | CO12: 0 | CP12: 0 | CQ12: 0 | CR12: - | CS12: 600 | CT12: - | CV12: Voucher 2,5GB | CW12: 12 | CX12: 116 | CY12: 86 | CZ12: 10 | DB12: 171 | DC12: 13500 | DD12: 2308500 | DF12: VDK | DG12: 138 | DH12: 100 | DI12: 0 | DJ12: 0 | DK12: 238 | DL12: 450 | DM12: 150 | DN12: 0 | DO12: 0 | DP12: 600 | DQ12: 162 | DR12: 27 | DS12: 0 | DT12: 0 | DU12: 189 | DV12: 150 | DW12: 450 | DX12: 0 | DY12: 0 | DZ12: 600 | EA12: 105 | EB12: 600 | EC12: 63000
A13: FI 3 GB | B13: 0 | C13: 0 | D13: =C13+B13 -> 0 | F13: Voucher 2,5GB | G13: 96 | H13: 104 | I13: 68 | J13: 202 | K13: 18 | L13: =SUM(G13:K13) -> 488 | Q13: Freedom Internet 3 GB | R13: =CM15 -> 0 | S13: =CW13 -> 0 | T13: =CN15 -> 0 | U13: =CX13 -> 0 | V13: =CO15 -> 0 | W13: =CY13 -> 0 | X13: =CP15 -> 0 | Y13: =CZ13 -> 0 | Z13: =R13+T13+V13+X13 -> 0 | AA13: =S13+U13+W13+Y13 -> 0 | AB13: 20000 | AC13: =AA13*AB13 -> 0 | AE13: SKBPLARA08 | AF13: Andi Sutiawan | AG13: =GETPIVOTDATA("Sum of QTY",$R$36,"Nama CSO","Andi Sutiawan") -> 313 | AH13: =15000*AG13 -> 4695000 | AI13: =AF5*15000 -> 5775000 | AJ13: =GETPIVOTDATA("Sum of Qty2",$R$36,"Nama CSO","Andi Sutiawan") -> 313 | AK13: =AG13-AJ13 -> 0 | AL13: =AJ13+AK13 -> 313 | AO13: 11 | AP13: 46209 | AQ13: GOL | AR13: MC-SAGARANTEN | AS13: 17792292 | AT13: Gilang cell 6 | AU13: Pebrian Sahri Ramdani | AV13: 9 | AW13: 0 | AX13: 27 | AY13: 0 | AZ13: 0 | BA13: 0 | BB13: 0 | BC13: 0 | BD13: 0 | BE13: 0 | BF13: 0 | BG13: 0 | BH13: 0 | BI13: 0 | BJ13: 0 | BK13: 0 | BL13: 0 | BM13: 0 | BN13: 9 | BO13: 675000 | BP13: 46209 | BQ13: 9 | BR13: 675000 | BS13: CASH | BT13: 0 | BU13: 46210 | BV13: 1700000 | BY13: 11 | BZ13: HIFI 3ID | CA13: 1 | CB13: 0895613208575 | CC13: 8962893000244846652 | CD13: 355806671150283 | CI13: STOK GUDANG | CL13: Voucher 3GB 14HR | CM13: 0 | CN13: 0 | CO13: 0 | CP13: 0 | CQ13: 0 | CR13: - | CS13: 22500 | CT13: - | CV13: Freedom Internet 3 GB | CW13: 0 | CX13: 0 | CY13: 0 | CZ13: 0 | DB13: 0 | DC13: 20000 | DD13: 0 | DF13: Voucher 3GB 14HR | DG13: 0 | DH13: 0 | DI13: 0 | DJ13: 0 | DK13: 0 | DL13: 0 | DM13: 0 | DN13: 0 | DO13: 0 | DP13: 0 | DQ13: 0 | DR13: 4 | DS13: 0 | DT13: 0 | DU13: 4 | DV13: 4 | DW13: 0 | DX13: 0 | DY13: 0 | DZ13: 4 | EA13: 0 | EB13: 22500 | EC13: 0
A14: 3.5GB 5HR | B14: 300 | C14: 71 | D14: =C14+B14 -> 371 | F14: Freedom Internet 3 GB | G14: 0 | H14: 0 | I14: 0 | J14: 0 | K14: 0 | L14: =SUM(G14:K14) -> 0 | O14: 2800000 | Q14: Voucher 3.5GB 5HR | R14: =CM16+AJ20 -> 0 | S14: =CW14+AJ5 -> 33 | T14: =CN16+AJ19 -> 0 | U14: =CX14+AJ4 -> 52 | V14: =CO16+AJ21 -> 0 | W14: =CY14+AJ6 -> 91 | X14: =CP16+AJ22 -> 0 | Y14: =CZ14+AJ7 -> 107 | Z14: =R14+T14+V14+X14 -> 0 | AA14: =S14+U14+W14+Y14 -> 283 | AB14: 15400 | AC14: =AA14*AB14 -> 4358200 | AE14: SKBPLARA11 | AF14: M. Enden Abdul Latif | AG14: =GETPIVOTDATA("Sum of QTY",$R$36,"Nama CSO","M. Enden Abdul Latif") -> 150 | AH14: =15000*AG14 -> 2250000 | AI14: 1500000 | AJ14: =GETPIVOTDATA("Sum of Qty2",$R$36,"Nama CSO","M. Enden Abdul Latif") -> 150 | AK14: =AG14-AJ14 -> 0 | AL14: =AJ14+AK14 -> 150 | AO14: 12 | AP14: 46210 | AQ14: GOL | AR14: MC-SAGARANTEN | AS14: 17253568 | AT14: AHZACELL | AU14: Kurnia | AV14: 2 | AW14: 0 | AX14: 6 | AY14: 0 | AZ14: 0 | BA14: 0 | BB14: 0 | BC14: 0 | BD14: 0 | BE14: 0 | BF14: 0 | BG14: 0 | BH14: 0 | BI14: 0 | BJ14: 0 | BK14: 0 | BL14: 0 | BM14: 0 | BN14: 2 | BO14: 150000 | BP14: 46210 | BQ14: 2 | BR14: 150000 | BS14: CASH | BT14: 0 | BU14: 46211 | BV14: 7500000 | BY14: 12 | BZ14: HIFI 3ID | CA14: 1 | CB14: 0895613208576 | CC14: 8962893000244846653 | CD14: 355806671150689 | CI14: STOK GUDANG | CL14: Voucher 2,5GB | CM14: 0 | CN14: 0 | CO14: 3 | CP14: 0 | CQ14: 3 | CR14: - | CS14: 13500 | CT14: - | CV14: Voucher 3.5GB 5HR | CW14: 6 | CX14: 19 | CY14: 10 | CZ14: 56 | DB14: 56 | DC14: 14500 | DD14: 812000 | DF14: Voucher 2,5GB | DG14: 0 | DH14: 12 | DI14: 0 | DJ14: 0 | DK14: 12 | DL14: 61 | DM14: 55 | DN14: 0 | DO14: 0 | DP14: 116 | DQ14: 61 | DR14: 25 | DS14: 0 | DT14: 0 | DU14: 86 | DV14: 10 | DW14: 0 | DX14: 0 | DY14: 0 | DZ14: 10 | EA14: 322 | EB14: 13500 | EC14: 4266000
A15: 5GB 5HR | B15: 450 | C15: 0 | D15: =C15+B15 -> 450 | F15: Voucher 3.5GB 5HR | G15: 9 | H15: 0 | I15: 35 | J15: 5 | K15: 0 | L15: =SUM(G15:K15) -> 49 | O15: 6800000 | Q15: Voucher 5GB 5HR | R15: =CM17 -> 0 | S15: =CW15 -> 12 | T15: =CN17 -> 0 | U15: =CX15 -> 146 | V15: =CO17 -> 0 | W15: =CY15 -> 50 | X15: =CP17 -> 10 | Y15: =CZ15 -> 60 | Z15: =R15+T15+V15+X15 -> 10 | AA15: =S15+U15+W15+Y15 -> 268 | AB15: 17250 | AC15: =AA15*AB15 -> 4623000 | AE15: DSESGRN01 | AF15: Pebrian Sahri Ramdani | AG15: =GETPIVOTDATA("Sum of QTY",$R$36,"Nama CSO","Pebrian Sahri Ramdani") -> 100 | AH15: =15000*AG15 -> 1500000 | AI15: =AF7*15000 -> 4920000 | AJ15: =GETPIVOTDATA("Sum of Qty2",$R$36,"Nama CSO","Pebrian Sahri Ramdani") -> 100 | AK15: =AG15-AJ15 -> 0 | AL15: =AJ15+AK15 -> 100 | AO15: 13 | AP15: 46210 | AQ15: GOL | AR15: MC-SAGARANTEN | AS15: 1348548 | AT15: MIRRA CELL | AU15: Pebrian Sahri Ramdani | AV15: 7 | AW15: 0 | AX15: 21 | AY15: 0 | AZ15: 0 | BA15: 0 | BB15: 0 | BC15: 0 | BD15: 0 | BE15: 0 | BF15: 0 | BG15: 0 | BH15: 0 | BI15: 0 | BJ15: 0 | BK15: 0 | BL15: 0 | BM15: 0 | BN15: 7 | BO15: 525000 | BP15: 46210 | BQ15: 7 | BR15: 525000 | BS15: CASH | BT15: 0 | BU15: 46211 | BV15: 450000 | BY15: 13 | BZ15: HIFI 3ID | CA15: 1 | CB15: 0895613208577 | CC15: 8962893000244846654 | CD15: 355806671131176 | CI15: STOK GUDANG | CL15: Freedom Internet 3 GB | CM15: 0 | CN15: 0 | CO15: 0 | CP15: 0 | CQ15: 0 | CR15: - | CS15: 20000 | CT15: - | CV15: Voucher 5GB 5HR | CW15: 12 | CX15: 146 | CY15: 50 | CZ15: 60 | DB15: 323 | DC15: 17250 | DD15: 5571750 | DF15: Freedom Internet 3 GB | DG15: 0 | DH15: 0 | DI15: 0 | DJ15: 0 | DK15: 0 | DL15: 0 | DM15: 0 | DN15: 0 | DO15: 0 | DP15: 0 | DQ15: 0 | DR15: 0 | DS15: 0 | DT15: 0 | DU15: 0 | DV15: 0 | DW15: 0 | DX15: 0 | DY15: 0 | DZ15: 0 | EA15: 0 | EB15: 20000 | EC15: 0
A16: 7GB 7HR | B16: =426 -> 426 | C16: 15 | D16: =C16+B16 -> 441 | F16: Voucher 5GB 5HR | G16: 32 | H16: 50 | I16: 23 | J16: 16 | K16: 18 | L16: =SUM(G16:K16) -> 139 | O16: 3950000 | Q16: Voucher 7GB 7HR | R16: =CM18 -> 0 | S16: =CW16 -> 0 | T16: =CN18 -> 0 | U16: =CX16 -> 34 | V16: =CO18 -> 0 | W16: =CY16 -> 0 | X16: =CP18 -> 0 | Y16: =CZ16 -> 3 | Z16: =R16+T16+V16+X16 -> 0 | AA16: =S16+U16+W16+Y16 -> 37 | AB16: 23800 | AC16: =AA16*AB16 -> 880600 | AG16: =SUM(AG12:AG15) -> 688 | AH16: =SUM(AH12:AH15) -> 10320000 | AI16: =SUM(AI12:AI15) -> 15480000 | AJ16: =SUM(AJ12:AJ15) -> 688 | AK16: =SUM(AK12:AK15) -> 0 | AL16: =SUM(AL12:AL15) -> 688 | AO16: 14 | AP16: 46211 | AQ16: GOL | AR16: MC-SAGARANTEN | AS16: 17729830 | AT16: Ryan store | AU16: Muhamad Parhan | AV16: 6 | AW16: 0 | AX16: 18 | AY16: 0 | AZ16: 0 | BA16: 0 | BB16: 0 | BC16: 0 | BD16: 0 | BE16: 0 | BF16: 0 | BG16: 0 | BH16: 0 | BI16: 0 | BJ16: 0 | BK16: 0 | BL16: 0 | BM16: 0 | BN16: 6 | BO16: 450000 | BP16: 46211 | BQ16: 6 | BR16: 450000 | BS16: CASH | BT16: 0 | BU16: 46212 | BV16: 1800000 | BY16: 14 | BZ16: HIFI 3ID | CA16: 1 | CB16: 0895613208578 | CC16: 8962893000244846655 | CD16: 355806671150630 | CI16: STOK GUDANG | CL16: Voucher 3.5GB 5HR | CM16: 0 | CN16: 0 | CO16: 0 | CP16: 0 | CQ16: 0 | CR16: - | CS16: 15400 | CT16: - | CV16: Voucher 7GB 7HR | CW16: 0 | CX16: 34 | CY16: 0 | CZ16: 3 | DB16: 92 | DC16: 23000 | DD16: 2116000 | DF16: Voucher 3.5GB 5HR | DG16: 0 | DH16: 6 | DI16: 0 | DJ16: 0 | DK16: 6 | DL16: 19 | DM16: 0 | DN16: 0 | DO16: 0 | DP16: 19 | DQ16: 10 | DR16: 0 | DS16: 0 | DT16: 0 | DU16: 10 | DV16: 0 | DW16: 56 | DX16: 0 | DY16: 0 | DZ16: 56 | EA16: 61 | EB16: 15400 | EC16: 939400
A17: Fi 6GB | B17: 0 | C17: 0 | D17: =C17+B17 -> 0 | F17: Voucher 7GB 7HR | G17: 15 | H17: 22 | I17: 24 | J17: 69 | K17: 16 | L17: =SUM(G17:K17) -> 146 | O17: 4070100 | Q17: Fi 6GB | R17: =CM19 -> 0 | S17: =CW17 -> 0 | T17: =CN19 -> 0 | U17: =CX17 -> 21 | V17: =CO19 -> 0 | W17: =CY17 -> 6 | X17: =CP19 -> 0 | Y17: =CZ17 -> 0 | Z17: =R17+T17+V17+X17 -> 0 | AA17: =S17+U17+W17+Y17 -> 27 | AB17: 30000 | AC17: =AA17*AB17 -> 810000 | AO17: 15 | AP17: 46211 | AQ17: GOL | AR17: MC-SAGARANTEN | AS17: 17737459 | AT17: WP - CACA CICI | AU17: M. Enden Abdul Latif | AV17: 12 | AW17: 0 | AX17: 36 | AY17: 0 | AZ17: 0 | BA17: 0 | BB17: 0 | BC17: 0 | BD17: 0 | BE17: 0 | BF17: 0 | BG17: 0 | BH17: 0 | BI17: 0 | BJ17: 0 | BK17: 0 | BL17: 0 | BM17: 0 | BN17: 12 | BO17: 900000 | BP17: 46211 | BQ17: 12 | BR17: 900000 | BS17: CASH | BT17: 0 | BU17: 46212 | BV17: 300000 | BY17: 15 | BZ17: HIFI 3ID | CA17: 1 | CB17: 0895613208583 | CC17: 8962893000244846660 | CD17: 355806671150622 | CI17: STOK GUDANG | CL17: Voucher 5GB 5HR | CM17: 0 | CN17: 0 | CO17: 0 | CP17: 10 | CQ17: 10 | CR17: 5 | CS17: 17250 | CT17: 86250 | CV17: Fi 6GB | CW17: 0 | CX17: 21 | CY17: 6 | CZ17: 0 | DB17: 24 | DC17: 30000 | DD17: 720000 | DF17: Voucher 5GB 5HR | DG17: 12 | DH17: 0 | DI17: 0 | DJ17: 0 | DK17: 12 | DL17: 76 | DM17: 70 | DN17: 0 | DO17: 0 | DP17: 146 | DQ17: 37 | DR17: 13 | DS17: 0 | DT17: 0 | DU17: 50 | DV17: 30 | DW17: 30 | DX17: 0 | DY17: 0 | DZ17: 60 | EA17: 593 | EB17: 17250 | EC17: 9780750
A18: Fi 1.5GB/1D | B18: 0 | C18: 51 | D18: =C18+B18 -> 51 | F18: Fi 6GB | G18: 0 | H18: 35 | I18: 0 | J18: 0 | K18: 0 | L18: =SUM(G18:K18) -> 35 | Q18: Fi 1.5GB/1D | R18: =CM20+AK20 -> 0 | S18: =CW18+AK5 -> 114 | T18: =CN20+AK19 -> 0 | U18: =CX18+AK4 -> 135 | V18: =CO20+AK21 -> 0 | W18: =CY18+AK6 -> 105 | X18: =CP20+AK22 -> 0 | Y18: =CZ18+AK7 -> 63 | Z18: =R18+T18+V18+X18 -> 0 | AA18: =S18+U18+W18+Y18 -> 417 | AB18: 6900 | AC18: =AA18*AB18 -> 2877300 | AF18: SP 3GB injek | AG18: SP 3GB | AH18: V 3GB 14H | AI18: V 2.5 GB | AJ18: V 3.5 GB | AK18: V 1.5 GB | AL18: VCR 5GB 3 | AO18: 16 | AP18: 46211 | AQ18: GOL | AR18: MC-SAGARANTEN | AS18: 572677 | AT18: Fitri cell | AU18: Pebrian Sahri Ramdani | AV18: 8 | AW18: 0 | AX18: 24 | AY18: 0 | AZ18: 0 | BA18: 0 | BB18: 0 | BC18: 0 | BD18: 0 | BE18: 0 | BF18: 0 | BG18: 0 | BH18: 0 | BI18: 0 | BJ18: 0 | BK18: 0 | BL18: 0 | BM18: 0 | BN18: 8 | BO18: 600000 | BP18: 46211 | BQ18: 8 | BR18: 600000 | BS18: CASH | BT18: 0 | BU18: 46212 | BV18: 5200000 | BY18: 16 | BZ18: HIFI 3ID | CA18: 1 | CB18: 0895613206960 | CC18: 8962893000244845180 | CD18: 355806670971960 | CI18: STOK GUDANG | CL18: Voucher 7GB 7HR | CM18: 0 | CN18: 0 | CO18: 0 | CP18: 0 | CQ18: 0 | CR18: - | CS18: 23800 | CT18: - | CV18: Fi 1.5GB/1D | CW18: 0 | CX18: 0 | CY18: 0 | CZ18: 0 | DB18: 0 | DC18: 6900 | DD18: 0 | DF18: Voucher 7GB 7HR | DG18: 0 | DH18: 0 | DI18: 0 | DJ18: 0 | DK18: 0 | DL18: 15 | DM18: 19 | DN18: 0 | DO18: 0 | DP18: 34 | DQ18: 0 | DR18: 0 | DS18: 0 | DT18: 0 | DU18: 0 | DV18: 0 | DW18: 3 | DX18: 0 | DY18: 0 | DZ18: 3 | EA18: 140 | EB18: 23800 | EC18: 3332000
A19: Fi 3GB/1D | B19: 0 | C19: 0 | D19: =C19+B19 -> 0 | F19: Fi 1.5GB/1D | G19: 0 | H19: 0 | I19: 0 | J19: 0 | K19: 0 | L19: =SUM(G19:K19) -> 0 | Q19: Fi 3GB/1D | R19: =CM21 -> 0 | S19: =CW19 -> 0 | T19: =CN21 -> 0 | U19: =CX19 -> 0 | V19: =CO21 -> 0 | W19: =CY19 -> 0 | X19: =CP21 -> 0 | Y19: =CZ19 -> 0 | Z19: =R19+T19+V19+X19 -> 0 | AA19: =S19+U19+W19+Y19 -> 0 | AB19: 7000 | AC19: =AA19*AB19 -> 0 | AE19: Muhamad Parhan | AO19: 17 | AP19: 46212 | AQ19: GOL | AR19: MC-SAGARANTEN | AS19: 17729987 | AT19: RE phonestore | AU19: Muhamad Parhan | AV19: 6 | AW19: 0 | AX19: 18 | AY19: 0 | AZ19: 0 | BA19: 0 | BB19: 0 | BC19: 0 | BD19: 0 | BE19: 0 | BF19: 0 | BG19: 0 | BH19: 0 | BI19: 0 | BJ19: 0 | BK19: 0 | BL19: 0 | BM19: 0 | BN19: 6 | BO19: 450000 | BP19: 46212 | BQ19: 6 | BR19: 450000 | BS19: CASH | BT19: 0 | BU19: 46213 | BV19: 400000 | CL19: Fi 6GB | CM19: 0 | CN19: 0 | CO19: 0 | CP19: 0 | CQ19: 0 | CR19: - | CS19: 30000 | CT19: - | CV19: Fi 3GB/1D | CW19: 0 | CX19: 0 | CY19: 0 | CZ19: 0 | DB19: 0 | DC19: 7000 | DD19: 0 | DF19: Fi 6GB | DG19: 0 | DH19: 0 | DI19: 0 | DJ19: 0 | DK19: 0 | DL19: 16 | DM19: 5 | DN19: 0 | DO19: 0 | DP19: 21 | DQ19: 6 | DR19: 0 | DS19: 0 | DT19: 0 | DU19: 6 | DV19: 0 | DW19: 0 | DX19: 0 | DY19: 0 | DZ19: 0 | EA19: 41 | EB19: 30000 | EC19: 1230000
A20: Fi 3GB/3D | B20: 0 | C20: 0 | D20: =C20+B20 -> 0 | F20: Fi 3GB/1D | G20: 0 | H20: 0 | I20: 0 | J20: 0 | K20: 0 | L20: =SUM(G20:K20) -> 0 | Q20: Fi 3GB/3D | R20: =CM22 -> 0 | S20: =CW20 -> 0 | T20: =CN22 -> 0 | U20: =CX20 -> 31 | V20: =CO22 -> 0 | W20: =CY20 -> 6 | X20: =CP22 -> 0 | Y20: =CZ20 -> 0 | Z20: =R20+T20+V20+X20 -> 0 | AA20: =S20+U20+W20+Y20 -> 37 | AB20: 12000 | AC20: =AA20*AB20 -> 444000 | AE20: Andi Sutiawan | AO20: 18 | AP20: 46212 | AQ20: GOL | AR20: MC-SAGARANTEN | AS20: 1295672 | AT20: RAYHAN CELL | AU20: M. Enden Abdul Latif | AV20: 7 | AW20: 0 | AX20: 21 | AY20: 0 | AZ20: 0 | BA20: 0 | BB20: 0 | BC20: 0 | BD20: 0 | BE20: 0 | BF20: 0 | BG20: 0 | BH20: 0 | BI20: 0 | BJ20: 0 | BK20: 0 | BL20: 0 | BM20: 0 | BN20: 7 | BO20: 525000 | BP20: 46212 | BQ20: 7 | BR20: 525000 | BS20: CASH | BT20: 0 | BU20: 46213 | BV20: 3950000 | CL20: Fi 1.5GB/1D | CM20: 0 | CN20: 0 | CO20: 0 | CP20: 0 | CQ20: 0 | CR20: - | CS20: 6900 | CT20: - | CV20: Fi 3GB/3D | CW20: 0 | CX20: 31 | CY20: 6 | CZ20: 0 | DB20: 12 | DC20: 12000 | DD20: 144000 | DF20: Fi 1.5GB/1D | DG20: 0 | DH20: 0 | DI20: 0 | DJ20: 0 | DK20: 0 | DL20: 0 | DM20: 0 | DN20: 0 | DO20: 0 | DP20: 0 | DQ20: 0 | DR20: 0 | DS20: 0 | DT20: 0 | DU20: 0 | DV20: 0 | DW20: 0 | DX20: 0 | DY20: 0 | DZ20: 0 | EA20: 0 | EB20: 6900 | EC20: 0
A21: Fi 5GB/2D | B21: 450 | C21: 904 | D21: =C21+B21 -> 1354 | F21: Fi 3GB/3D | G21: 11 | H21: 14 | I21: 9 | J21: 0 | K21: 0 | L21: =SUM(G21:K21) -> 34 | Q21: Fi 5GB/2D | R21: =CM23 -> 0 | S21: =CW21 -> 65 | T21: =CN23 -> 10 | U21: =CX21 -> 76 | V21: =CO23 -> 4 | W21: =CY21 -> 42 | X21: =CP23 -> 0 | Y21: =CZ21 -> 27 | Z21: =R21+T21+V21+X21 -> 14 | AA21: =S21+U21+W21+Y21 -> 210 | AB21: 9600 | AC21: =AA21*AB21 -> 2016000 | AE21: M. Enden Abdul Latif | AO21: 19 | AP21: 46212 | AQ21: GOL | AR21: MC-SAGARANTEN | AS21: 1554004 | AT21: MANDIRI CELL | AU21: Pebrian Sahri Ramdani | AV21: 6 | AW21: 0 | AX21: 18 | AY21: 0 | AZ21: 0 | BA21: 0 | BB21: 0 | BC21: 0 | BD21: 0 | BE21: 0 | BF21: 0 | BG21: 0 | BH21: 0 | BI21: 0 | BJ21: 0 | BK21: 0 | BL21: 0 | BM21: 0 | BN21: 6 | BO21: 450000 | BP21: 46212 | BQ21: 6 | BR21: 450000 | BS21: CASH | BT21: 0 | BU21: 46213 | BV21: 800000 | CL21: Fi 3GB/1D | CM21: 0 | CN21: 0 | CO21: 0 | CP21: 0 | CQ21: 0 | CR21: - | CS21: 7000 | CT21: - | CV21: Fi 5GB/2D | CW21: 65 | CX21: 76 | CY21: 42 | CZ21: 27 | DB21: 253 | DC21: 9600 | DD21: 2428800 | DF21: Fi 3GB/1D | DG21: 0 | DH21: 0 | DI21: 0 | DJ21: 0 | DK21: 0 | DL21: 0 | DM21: 0 | DN21: 0 | DO21: 0 | DP21: 0 | DQ21: 0 | DR21: 0 | DS21: 0 | DT21: 0 | DU21: 0 | DV21: 0 | DW21: 0 | DX21: 0 | DY21: 0 | DZ21: 0 | EA21: 1 | EB21: 7000 | EC21: 7000
A22: Fi 5GB/3D | B22: 207 | C22: 10 | D22: =C22+B22 -> 217 | F22: Fi 5GB/2D | G22: 25 | H22: 15 | I22: 96 | J22: 92 | K22: 12 | L22: =SUM(G22:K22) -> 240 | Q22: Fi 5GB/3D | R22: =CM24+AL20 -> 0 | S22: =CW22+AL4 -> 0 | T22: =CN24+AL19 -> 0 | U22: =CX22+AL4 -> 4 | V22: =CO24+AL21 -> 0 | W22: =CY22+AL6 -> 0 | X22: =CP24+AL22 -> 0 | Y22: =CZ22+AL7 -> 1 | Z22: =R22+T22+V22+X22 -> 0 | AA22: =S22+U22+W22+Y22 -> 5 | AB22: 13200 | AC22: =AA22*AB22 -> 66000 | AE22: Pebrian Sahri Ramdani | AO22: 20 | AP22: 46212 | AQ22: GOL | AR22: MC-SAGARANTEN | AS22: 1554004 | AT22: MANDIRI CELL | AU22: Kurnia | AV22: 2 | AW22: 0 | AX22: 6 | AY22: 0 | AZ22: 0 | BA22: 0 | BB22: 0 | BC22: 0 | BD22: 0 | BE22: 0 | BF22: 0 | BG22: 0 | BH22: 0 | BI22: 0 | BJ22: 0 | BK22: 0 | BL22: 0 | BM22: 0 | BN22: 2 | BO22: 150000 | BP22: 46212 | BQ22: 2 | BR22: 150000 | BS22: CASH | BT22: 0 | BU22: 46213 | BV22: 800000 | CL22: Fi 3GB/3D | CM22: 0 | CN22: 0 | CO22: 0 | CP22: 0 | CQ22: 0 | CR22: - | CS22: 12000 | CT22: - | CV22: Fi 5GB/3D | CW22: 0 | CX22: 4 | CY22: 0 | CZ22: 1 | DB22: 0 | DC22: 13200 | DD22: 0 | DF22: Fi 3GB/3D | DG22: 0 | DH22: 0 | DI22: 0 | DJ22: 0 | DK22: 0 | DL22: 31 | DM22: 0 | DN22: 0 | DO22: 0 | DP22: 31 | DQ22: 6 | DR22: 0 | DS22: 0 | DT22: 0 | DU22: 6 | DV22: 0 | DW22: 0 | DX22: 0 | DY22: 0 | DZ22: 0 | EA22: 56 | EB22: 12000 | EC22: 672000
A23: 7GB 28HR | B23: 300 | D23: =C23+B23 -> 300 | F23: Fi 5GB/3D | G23: 15 | H23: 0 | I23: 3 | J23: 54 | K23: 9 | L23: =SUM(G23:K23) -> 81 | S23: 0 | U23: 0 | V23: =CO25 -> 0 | W23: 0 | X23: =CP25 -> 0 | Y23: 0 | Z23: =R23+T23+V23+X23 -> 0 | AA23: 0 | AC23: 0 | AF23: 200 | AG23: 348 | AH23: 48 | AI23: 219 | AJ23: 129 | AK23: 300 | AL23: - | AO23: 21 | AP23: 46213 | AQ23: GOL | AR23: MC-SAGARANTEN | AT23: #N/A | AU23: Muhamad Parhan | AV23: 32 | AW23: 0 | AX23: 96 | AY23: 0 | AZ23: 0 | BA23: 0 | BB23: 0 | BC23: 0 | BD23: 0 | BE23: 0 | BF23: 0 | BG23: 0 | BH23: 0 | BI23: 0 | BJ23: 0 | BK23: 0 | BL23: 0 | BM23: 0 | BN23: 32 | BO23: 2400000 | BT23: 2400000 | BV23: 0 | CL23: Fi 5GB/2D | CM23: 0 | CN23: 10 | CO23: 4 | CP23: 0 | CQ23: 14 | CR23: 24 | CS23: 9600 | CT23: 230400 | CV23: TOTAL VOUCHER | CW23: 364 | CX23: 523 | CY23: 370 | CZ23: 284 | DA23: 76 | DB23: 1617 | DD23: 29053050 | DF23: Fi 5GB/2D | DG23: 30 | DH23: 35 | DI23: 0 | DJ23: 0 | DK23: 65 | DL23: 13 | DM23: 63 | DN23: 0 | DO23: 0 | DP23: 76 | DQ23: 35 | DR23: 7 | DS23: 0 | DT23: 0 | DU23: 42 | DV23: 12 | DW23: 15 | DX23: 0 | DY23: 0 | DZ23: 27 | EA23: 434 | EB23: 9600 | EC23: 4070400
